Workbook
Name aaaa: '[1]Machine rates'!$B$10:$B$239
Name cellAssumptionLifetime: #REF!
Name cellAssumptionMatOvhPurchParts: #REF!
Name cellAssumptionMatOvhRawMaterial: #REF!
Name cellAssumptionPartName: #REF!
Name cellAssumptionProductName: #REF!
Name cellAssumptionSupplier: #REF!
Name cellAssumptionVolumePerYear: #REF!
Name colEmb_Item: #REF!
Name colEmb_Mat_PurchItems: #REF!
Name colEmb_Mat_RawMat: #REF!
Name colEmb_Total: #REF!
Name colEmb_VA_Labor: #REF!
Name colEmb_VA_Machinery: #REF!
Name colEmb_VA_ToolRepl: #REF!
Name colMatVA_Code: #REF!
Name colMatVA_Description: #REF!
Name colMatVA_Mat_Descr: #REF!
Name colMatVA_Mat_GroupIdent: #REF!
Name colMatVA_Mat_Purch_CostPerItem: #REF!
Name colMatVA_Mat_Purch_Remark: #REF!
Name colMatVA_Mat_PurchTotal: #REF!
Name colMatVA_Mat_RawMat_CostsPerUnit: #REF!
Name colMatVA_Mat_RawMat_Density: #REF!
Name colMatVA_Mat_RawMat_Diameter: #REF!
Name colMatVA_Mat_RawMat_FinalPart: #REF!
Name colMatVA_Mat_RawMat_InitUsage: #REF!
Name colMatVA_Mat_RawMat_Length: #REF!
Name colMatVA_Mat_RawMat_Surchage: #REF!
Name colMatVA_Mat_RawMat_Thickness: #REF!
Name colMatVA_Mat_RawMat_Total: #REF!
Name colMatVA_Mat_RawMat_unit: #REF!
Name colMatVA_Mat_RawMat_Width: #REF!
Name colMatVA_Mat_Total: #REF!
Name colMatVA_Module: #REF!
Name colMatVA_PreRef: #REF!
Name colMatVA_Quantity: #REF!
Name colMatVA_Ref: #REF!
Name colMatVA_Total: #REF!
Name colMatVA_VA_Descr: #REF!
Name colMatVA_VA_Labor_FTE: #REF!
Name colMatVA_VA_Labor_OLE: #REF!
Name colMatVA_VA_Labor_Rate: #REF!
Name colMatVA_VA_Labor_Skill: #REF!
Name colMatVA_VA_LaborTotal: #REF!
Name colMatVA_VA_Machinery_Descr: #REF!
Name colMatVA_VA_Machinery_Descr: #REF!
Name colMatVA_VA_Machinery_Descr: #REF!
Name colMatVA_VA_Machinery_MMR: #REF!
Name colMatVA_VA_Machinery_OutputPerYear: #REF!
Name colMatVA_VA_MachineryTotal: #REF!
Name colMatVA_VA_Perf_Cycletime: #REF!
Name colMatVA_VA_Perf_PartsPerCycle: #REF!
Name colMatVA_VA_Tool_CostPerTool: #REF!
Name colMatVA_VA_Tool_Lifetime: #REF!
Name colMatVA_VA_Tool_Remark: #REF!
Name colMatVA_VA_Tool_UpfrontPaid: #REF!
Name colMatVA_VA_ToolReplTotal: #REF!
Name colMatVA_VA_Total: #REF!
Name colMatVA_Yield: #REF!

Sheet Summary
B2: Component Details | E2: Buyer Details | J2: Vendor Details
B3: Part No | C3: ='INPUT - OUTPUT'!C6:D6 -> FXB01800_Assy01_Item24 | E3: Cost estimator | J3: Vendor Code
B4: Descrtiption | C4: ='INPUT - OUTPUT'!C5:D5 -> Fixed finger | E4: Project | J4: Name
B5: Part Family | J5: Location
B6: Clean Sheet Costing - Breakup details
B7: Cost Head | C7: Raw Material Cost | D7: Allowance | E7: Process Cost | F7: Manufacturing Cost | G7: Overhead | H7: Profit | I7: Total Basic Cost | J7: Packing | K7: Transport Cost | L7: Tool Cost Amortization | M7: Total Cost
B8: Amount | C8: =Material!T11 -> 68.4403 | D8: =Material!U11 -> 19.11137 | E8: ='INPUT - OUTPUT'!H8 -> 86.417451 | F8: =E8+D8+C8 -> 173.96912 | G8: ='INPUT - OUTPUT'!H13+'INPUT - OUTPUT'!H15 -> 44.84296 | H8: ='INPUT - OUTPUT'!H14 -> 13.91753 | I8: =H8+G8+F8 -> 232.72961 | J8: 0 | K8: 0 | L8: 0 | M8: =SUM(I8:L8) -> 232.72961
B9: Ratio | C9: =C8/$I$8 -> 0.29407646 | D9: =D8/$I$8 -> 0.082118345 | E9: =E8/$I$8 -> 0.37132125 | F9: =E9+D9+C9 -> 0.74751606 | G9: =G8/$I$8 -> 0.19268266 | H9: =H8/$I$8 -> 0.059801285 | I9: =I8/$I$8 -> 1 | J9: =J8/$I$8 -> 0 | K9: =K8/$I$8 -> 0 | L9: =L8/$I$8 -> 0 | M9: =M8/$I$8 -> 1
B10: Clean Sheet Costing - Chart
C33: Raw Material Cost | D33: Allowance | E33: Process Cost | F33: Manufacturing Cost | G33: Overhead | H33: Profit | I33: Basic Cost | J33: Packing | K33: Transport Cost | L33: Tool Cost Amortization | M33: Total Cost
D34: =C35 -> 68.4403 | E34: =D34+D35 -> 87.55167 | G34: =F35 -> 173.96912 | H34: =G34+G35 -> 218.81208 | J34: =I35 -> 232.72961 | K34: =J34+J35 -> 232.72961 | L34: =K35+K34 -> 232.72961
C35: =C8 -> 68.4403 | D35: =D8 -> 19.11137 | E35: =E8 -> 86.417451 | F35: =E35+E34 -> 173.96912 | G35: =G8 -> 44.84296 | H35: =H8 -> 13.91753 | I35: =H35+H34 -> 232.72961 | J35: =J8 -> 0 | K35: =K8 -> 0 | L35: =L8 -> 0 | M35: =L35+L34 -> 232.72961
B40: Revision | C40: Manufacturing Cost added

Sheet INPUT - OUTPUT
B4: INTRODUCTION | G4: COST HEAD | H4: CS Cost | I4: Client Cost
B5: Part Name | C5: Fixed finger | G5: RM Cost | H5: =Material!R10 -> 87.55167
B6: Part No | C6: FXB01800_Assy01_Item24 | G6: BOP Cost | H6: =Material!R11 -> 0
B7: Revision | C7: #3 | G7: Total RM cost | H7: =SUM(H5:H6) -> 87.55167
B8: Supplier Category | C8: A | G8: Total Conversion cost | H8: =PROCESS!$O$2 -> 86.417451
B9: Date of estimation | C9: 44718 | G9: ICC | H9: =C15*H7 -> 1.9699126
B10: RM data base | C10: 44652 | G10: Rej on RM | H10: =C16*(H7) -> 0.43775835
B11: Conversion data base | C11: 43466 | G11: Rej on Conv | H11: =C17*(H8) -> 0.86417451
G12: Tool maintenance cost | H12: =C18*(H8) -> 1.728349
G13: OH | H13: =$C$19*(H8) -> 12.962618
B14: COST HEADS | G14: Profit | H14: =C20*(H7+H8) -> 13.91753
B15: ICC | C15: 0.0225 | D15: RM | G15: OTHER COST | H15: =SUM(H9:H14) -> 31.880342
B16: Rejection | C16: 0.005 | D16: RM | G16: TOTAL COST | H16: =H15+H8+H7 -> 205.84946 | I16: =H16/H17 -> 324.17238
B17: Rejection | C17: 0.01 | D17: Conv | G17: Total Finish weight(kg) | H17: =Material!I13 -> 0.635
B18: Tool maintenance | C18: 0.02 | D18: Conv
B19: OH | C19: =IF(C8="A",15%,IF(C8="B",12%,10%)) -> 0.15 | D19: Conv | G19: KEY RATIOS | H19: %
B20: Profit | C20: =IF(C8="A",8%,IF(C8="B",6%,5%)) -> 0.08 | D20: RM+Conv | G20: RM Cost / Total Cost | H20: =H7/$H$16 -> 0.42531891
G21: VA / Total Cost | H21: =H8/$H$16 -> 0.41980897
G22: Other Cost / Total Cost | H22: =H15/$H$16 -> 0.15487212
C65: USD
C66: POUNDS
C67: EURO
C68: YEN
C69: INR

Sheet Material
A10: Material | Q10: RM | R10: =SUMIF($D$12:$D$1048576,$Q10,$R$12:$R$99) -> 87.55167
J11: If known or calculated, otherwise | Q11: BOP | R11: =SUMIF($D$12:$D$1048576,$Q11,$R$12:$R$99) -> 0 | T11: =SUM(T13:T200) -> 68.4403 | U11: =SUM(U13:U200) -> 19.11137
A12: S.No | B12: Part no | C12: Item Description | D12: RM/ BOP | E12: Material Grade | F12: Quantity | G12: RM price /kg | H12: Scrap Price/kg | I12: Weight (kg) | J12: Machining Allowance | K12: Forged Weight (kg) | L12: Billet Weight (kg) | M12: Input weight (kg) | N12: Burning Loss | O12: Scrap wt(kg) | P12: Scrap Reutilization | Q12: Price per unit (INR) | R12: Total Price per Line item (INR) | S12: Remarks | T12: Direct RM Cost | U12: Allowance cost
A13: 1 | B13: FXB01800_Assy02_Item08 | C13: Piston rod | D13: RM | E13: EN353 | F13: 1 | G13: =97.78+10 -> 107.78 | H13: 32 | I13: 0.635 | J13: =G40*1.1 -> 0.14524916 | K13: =I13+J13 -> 0.78024916 | L13: =K13*(1.05+N13) -> 0.8426691 | M13: =L13*(1+0.02) -> 0.85952248 | N13: 0.03 | O13: =M13-I13-(N13*M13) -> 0.1987368 | P13: 0.8 | Q13: =M13*G13-(O13*P13*H13) -> 87.55167 | R13: =Q13*F13 -> 87.55167 | T13: =I13*G13*F13 -> 68.4403 | U13: =R10-T13 -> 19.11137
C15: Chemical Composition of EN353 | H15: Finished wt | I15: 6.83
C17: C | D17: Mn | E17: Si | F17: S | G17: P | H17: Cr | I17: Ni | J17: Mo
B18: EN - 353 | C18: .20 MAX | D18: .50 - 1.00 | E18: .35 MAX | F18: 0.04 | G18: 0.04 | H18: .75 - 1.25 | I18: 1.00 - 1.50 | J18: .08 - .15
C21: Chemical composition % of grade 17NiCrMo6-4 (1.6566): EN 10084-2008
C23: C | D23: Si | E23: Mn | F23: Ni | G23: P | H23: S | I23: Cr | J23: Mo
C24: 0.14 - 0.2 | D24: max 0.4 | E24: 0.6 - 0.9 | F24: 1.2 - 1.5 | G24: max 0.025 | H24: 0.02 - 0.04 | I24: 0.8 - 1.1 | J24: 0.15 - 0.25
B27: Machining allowance
B29: S.No | C29: Side | D29: Dia-before machinig | E29: Dia-after machining | F29: Length
B30: 1 | C30: Step turning 1 | D30: =E30+2 -> 26 | E30: 24 | F30: 140 | G30: =3.14*((D30/1000)^2-(E30/1000)^2)*0.25*F30/1000*7850 -> 0.0862715
B31: 2 | C31: Step turning 2 | D31: =E31+2 -> 22 | E31: 20 | F31: 6 | G31: =3.14*((D31/1000)^2-(E31/1000)^2)*0.25*F31/1000*7850 -> 0.003105774
B32: 3 | C32: Step turning 3 | D32: =E32+2 -> 24 | E32: 22 | F32: 12 | G32: =3.14*((D32/1000)^2-(E32/1000)^2)*0.25*F32/1000*7850 -> 0.006803124
B33: 4 | C33: Step turning 4 | D33: =E33+2 -> 16 | E33: 14 | F33: 20 | G33: =3.14*((D33/1000)^2-(E33/1000)^2)*0.25*F33/1000*7850 -> 0.0073947
B34: 5 | C34: Step turning 5 | D34: =E34+2 -> 22 | E34: 20 | F34: 55 | G34: =3.14*((D34/1000)^2-(E34/1000)^2)*0.25*F34/1000*7850 -> 0.028469595
G40: =SUM(G30:G39) -> 0.13204469

Sheet PROCESS
A1: PROCESS
M2: =SUM(M5:M31) -> 85.584118 | O2: =SUM(O5:O120) -> 86.417451
A3: S NO | B3: ITEM DESCRIPTION | C3: PROCESS DESCRIPTION | D3: QTY | F3: MACHINERY COST | O3: TOTAL VALUE ADD | P3: REMARKS
F4: Operation | G4: SC1 | H4: Norms Rs/Unit | I4: UOM | J4: Units | K4: Time in Sec | L4: Parts Per unit | M4: Cost/part
A5: A | C5: Forging Process | D5: 1 | F5: Forging | H5: 18 | I5: per kg | J5: =Material!L13 -> 0.8426691 | M5: =H5*J5 -> 15.168044 | O5: =M5*D5 -> 15.168044
A6: C | C6: Heat treatment-Hardening & Tempering | D6: 1 | F6: Hardening & Tempering | H6: 8 | I6: per kg | J6: =Material!K13 -> 0.78024916 | M6: =H6*J6 -> 6.2419933 | O6: =M6*D6 -> 6.2419933
A7: D | C7: Shot blasting | D7: 1 | F7: Shot blasting | H7: 3 | I7: per kg | J7: =J6 -> 0.78024916 | M7: =H7*J7 -> 2.3407475 | O7: =M7*D7 -> 2.3407475
A8: F | C8: Visual inspection | D8: 1 | F8: Inspection | G8: Approx | H8: 5 | I8: per part | J8: 1 | M8: =H8*J8 -> 5 | O8: =M8*D8 -> 5
A9: 1 | B9: Soft Machining | C9: Loading to the machine | D9: 1 | F9: CNC | G9: Size 3 | H9: 300 | I9: per hr | K9: 30 | L9: 1 | M9: =H9/3600*K9 -> 2.5 | O9: =M9*D9 -> 2.5
C10: Facing operation | D10: 1 | F10: CNC | G10: Size 3 | H10: 300 | I10: per hr | K10: 15 | L10: 1 | M10: =H10/3600*K10 -> 1.25 | O10: =M10*D10 -> 1.25
A11: 2 | C11: Centre hole drilling operation-side1 | D11: 1 | F11: CNC | G11: Size 3 | H11: 300 | I11: per hr | K11: 15 | L11: 1 | M11: =H11/3600*K11 -> 1.25 | O11: =M11*D11 -> 1.25
A12: 2 | C12: Chamfering operation | D12: 1 | F12: CNC | G12: Size 3 | H12: 300 | I12: per hr | K12: 10 | L12: 1 | M12: =H12/3600*K12 -> 0.83333333 | O12: =M12*D12 -> 0.83333333
A13: 6 | C13: Step turning operation | D13: 1 | F13: CNC | G13: Size 3 | H13: 300 | I13: per hr | K13: 60 | L13: 1 | M13: =H13/3600*K13 -> 5 | O13: =M13*D13 -> 5
A14: 6 | C14: Grooving operation | D14: 2 | F14: CNC | G14: Size 3 | H14: 300 | I14: per hr | K14: 10 | L14: 1 | M14: =H14/3600*K14 -> 0.83333333 | O14: =M14*D14 -> 1.6666667
A15: 6 | C15: Unloading from the machine | D15: 1 | F15: CNC | G15: Size 3 | H15: 300 | I15: per hr | K15: 30 | L15: 1 | M15: =H15/3600*K15 -> 2.5 | O15: =M15*D15 -> 2.5
A16: 1 | C16: Loading to the machine | D16: 1 | F16: CNC | G16: Size 3 | H16: 300 | I16: per hr | K16: 30 | L16: 1 | M16: =H16/3600*K16 -> 2.5 | O16: =M16*D16 -> 2.5
C17: Facing operation | D17: 1 | F17: CNC | G17: Size 3 | H17: 300 | I17: per hr | K17: 42 | L17: 1 | M17: =H17/3600*K17 -> 3.5 | O17: =M17*D17 -> 3.5
A18: 2 | C18: Centre hole drilling operation-side2 | D18: 1 | F18: CNC | G18: Size 3 | H18: 300 | I18: per hr | K18: 40 | L18: 1 | M18: =H18/3600*K18 -> 3.3333333 | O18: =M18*D18 -> 3.3333333
A19: 2 | C19: Chamfering operation | D19: 1 | F19: CNC | G19: Size 3 | H19: 300 | I19: per hr | K19: 10 | L19: 1 | M19: =H19/3600*K19 -> 0.83333333 | O19: =M19*D19 -> 0.83333333
A20: 6 | C20: Step turning operation | D20: 1 | F20: CNC | G20: Size 3 | H20: 300 | I20: per hr | K20: 60 | L20: 1 | M20: =H20/3600*K20 -> 5 | O20: =M20*D20 -> 5
A21: 6 | C21: Unloading from the machine | D21: 1 | F21: CNC | G21: Size 3 | H21: 300 | I21: per hr | K21: 30 | L21: 1 | M21: =H21/3600*K21 -> 2.5 | O21: =M21*D21 -> 2.5
A22: 1 | C22: Loading to the machine | D22: 1 | F22: Drilling machine | H22: 100 | I22: per hr | K22: 30 | L22: 1 | M22: =H22/3600*K22 -> 0.83333333 | O22: =M22*D22 -> 0.83333333
A23: 6 | C23: Drilling operation | D23: 1 | F23: Drilling machine | H23: 100 | I23: per hr | K23: 60 | L23: 1 | M23: =H23/3600*K23 -> 1.6666667 | O23: =M23*D23 -> 1.6666667
A24: 6 | C24: Countersunkoperation | D24: 1 | F24: Drilling machine | H24: 100 | I24: per hr | K24: 20 | L24: 1 | M24: =H24/3600*K24 -> 0.55555556 | O24: =M24*D24 -> 0.55555556
C25: Indexing operation | D25: 1 | F25: Drilling machine | H25: 100 | I25: per hr | K25: 20 | L25: 1 | M25: =H25/3600*K25 -> 0.55555556 | O25: =M25*D25 -> 0.55555556
A26: 6 | C26: Countersunkoperation | D26: 1 | F26: Drilling machine | H26: 100 | I26: per hr | K26: 20 | L26: 1 | M26: =H26/3600*K26 -> 0.55555556 | O26: =M26*D26 -> 0.55555556
A27: 6 | C27: Unloading from the machine | D27: 1 | F27: Drilling machine | H27: 100 | I27: per hr | K27: 30 | L27: 1 | M27: =H27/3600*K27 -> 0.83333333 | O27: =M27*D27 -> 0.83333333
B28: Hard machining | C28: Loading to the Cylindrcal grinding | D28: 1 | F28: CNC-Cylindrical grinder | G28: Size 3 | H28: 300 | I28: per hr | K28: 60 | L28: 1 | M28: =H28/3600*K28 -> 5 | O28: =M28*D28 -> 5
A29: 3 | C29: Finish Grinding operation | D29: 1 | F29: CNC-Cylindrical grinder | G29: Size 3 | H29: 300 | I29: per hr | K29: 90 | L29: 1 | M29: =H29/3600*K29 -> 7.5 | O29: =M29*D29 -> 7.5
A30: 5 | C30: Unloading from the Cylindrcal grinding | D30: 1 | F30: CNC-Cylindrical grinder | G30: Size 3 | H30: 300 | I30: per hr | K30: 30 | L30: 1 | M30: =H30/3600*K30 -> 2.5 | O30: =M30*D30 -> 2.5
A31: 24 | C31: Dressing & inspection | D31: 1 | F31: Manual Process | M31: 5 | O31: =M31*D31 -> 5
B34: 2/kg on casting wt | C34: Shot blasting | F34: Drilling
B35: 7/kg on cast wt | C35: Impregnation | F35: Ø | G35: Depth | H35: CS | I35: RPM | J35: Feed mm/rev | K35: Time
B36: 5 | C36: Leak test | F36: 6 | G36: 30 | H36: 120 | I36: =H36*1000/(PI()*F36) -> 6366.1977 | J36: 0.05 | K36: =(G36+12)/(I36*J36/60)+5 -> 12.916813
B37: 5 | C37: Cleaning
F38: Milling
F39: Cutter Ø | G39: Length | H39: Width | I39: No of pass | J39: No of insert | K39: CS | L39: RPM | M39: Feed mm/rev | N39: Time
F40: 10 | G40: 125 | H40: 60 | I40: 1 | J40: 1 | K40: 600 | L40: =K40*1000/(PI()*F40) -> 19098.593 | M40: =0.1*J40 -> 0.1 | N40: =((G40+(F40+10)+IF(H40<F40,0,((CEILING(H40/F40,1)-1)*G40)+((CEILING(H40/F40,1)-1)*F40)))/(M40*L40/60)+5)*I40 -> 30.76106
F43: 5 seconds considered for rapid movement
F44: 5 seconds considered for centre drilling
...

Sheet Back up RM
B2: Sr. No. | C2: RM | D2: Rs/kg | E2: Source
B3: 1 | C3: Pig Iron | D3: 29.770646
B4: 2 | C4: Steel Scrap | D4: 24.7248
B5: 3 | C5: CPC | D5: 38.659333 | N5: Forklift Truck (2 ton)
B6: 4 | C6: FeSi | D6: 95.71 | N6: Material Loading
B7: 5 | C7: FeMn | D7: 59.678 | N7: Band saw
B8: 6 | C8: Fe-Cr | D8: 271.929 | N8: Material Loading
B9: 7 | C9: FeS | D9: 87.828 | N9: Trolley (1 ton)
B10: 8 | C10: Cu | D10: 423 | N10: Induction Furnace
B11: 9 | C11: Sn | D11: 1670.2333 | N11: Material Loading
B12: 10 | C12: Mg | D12: 189.168 | N12: Manual Process
B13: 11 | C13: Inoculation | D13: 136.62133 | N13: Manual Process
B14: 12 | C14: New Sand | D14: 2.05 | N14: Rolling
B15: 13 | C15: Bentonite | D15: 4.85 | N15: 3t-Forging Hammer
B16: 14 | C16: Coal Dust | D16: 17.55 | N16: Manual Process
... B22: 20 | C22: IS: 3073 | D22: 38 | N22: Tempering furnace
B23: 21 | N23: Trolley (1 ton)
B24: 22 | N24: Shot blasting
B25: 23 | N25: Manual Process
B26: 24 | N26: Material Loading
B27: 25
B28: 26
B29: 27
B30: 28
B31: 29
B32: 30
B33: 31
B34: 32
B35: 33
B36: 34
B37: 35
