Workbook
Name aaaa: '[1]Machine rates'!$B$10:$B$239
Name cellAssumptionLifetime: #REF!
Name cellAssumptionMatOvhPurchParts: #REF!
Name cellAssumptionMatOvhRawMaterial: #REF!
Name cellAssumptionPartName: #REF!
Name cellAssumptionProductName: #REF!
Name cellAssumptionSupplier: #REF!
Name cellAssumptionVolumePerYear: #REF!
Name colEmb_Item: #REF!
Name colEmb_Mat_PurchItems: #REF!
Name colEmb_Mat_RawMat: #REF!
Name colEmb_Total: #REF!
Name colEmb_VA_Labor: #REF!
Name colEmb_VA_Machinery: #REF!
Name colEmb_VA_ToolRepl: #REF!
Name colMatVA_Code: #REF!
Name colMatVA_Description: #REF!
Name colMatVA_Mat_Descr: #REF!
Name colMatVA_Mat_GroupIdent: #REF!
Name colMatVA_Mat_Purch_CostPerItem: #REF!
Name colMatVA_Mat_Purch_Remark: #REF!
Name colMatVA_Mat_PurchTotal: #REF!
Name colMatVA_Mat_RawMat_CostsPerUnit: #REF!
Name colMatVA_Mat_RawMat_Density: #REF!
Name colMatVA_Mat_RawMat_Diameter: #REF!
Name colMatVA_Mat_RawMat_FinalPart: #REF!
Name colMatVA_Mat_RawMat_InitUsage: #REF!
Name colMatVA_Mat_RawMat_Length: #REF!
Name colMatVA_Mat_RawMat_Surchage: #REF!
Name colMatVA_Mat_RawMat_Thickness: #REF!
Name colMatVA_Mat_RawMat_Total: #REF!
Name colMatVA_Mat_RawMat_unit: #REF!
Name colMatVA_Mat_RawMat_Width: #REF!
Name colMatVA_Mat_Total: #REF!
Name colMatVA_Module: #REF!
Name colMatVA_PreRef: #REF!
Name colMatVA_Quantity: #REF!
Name colMatVA_Ref: #REF!
Name colMatVA_Total: #REF!
Name colMatVA_VA_Descr: #REF!
Name colMatVA_VA_Labor_FTE: #REF!
Name colMatVA_VA_Labor_OLE: #REF!
Name colMatVA_VA_Labor_Rate: #REF!
Name colMatVA_VA_Labor_Skill: #REF!
Name colMatVA_VA_LaborTotal: #REF!
Name colMatVA_VA_Machinery_Descr: #REF!
Name colMatVA_VA_Machinery_Descr: #REF!
Name colMatVA_VA_Machinery_Descr: #REF!
Name colMatVA_VA_Machinery_MMR: #REF!
Name colMatVA_VA_Machinery_OutputPerYear: #REF!
Name colMatVA_VA_MachineryTotal: #REF!
Name colMatVA_VA_Perf_Cycletime: #REF!
Name colMatVA_VA_Perf_PartsPerCycle: #REF!
Name colMatVA_VA_Tool_CostPerTool: #REF!
Name colMatVA_VA_Tool_Lifetime: #REF!
Name colMatVA_VA_Tool_Remark: #REF!
Name colMatVA_VA_Tool_UpfrontPaid: #REF!
Name colMatVA_VA_ToolReplTotal: #REF!
Name colMatVA_VA_Total: #REF!
Name colMatVA_Yield: #REF!

Sheet INPUT - OUTPUT
B4: INTRODUCTION | G4: COST HEAD | H4: CS Cost | I4: Client Cost
B5: Part Name | C5: Piston head | G5: RM Cost | H5: =MATERIAL!Z11 -> 143.85506
B6: Part No | C6: FXB01800_Assy02_Item05 | G6: BOP Cost | H6: =MATERIAL!Z12 -> 0
B7: Revision | C7: #3 | G7: TOTAL RM COST | H7: =SUM(H5:H6) -> 143.85506
B8: Supplier Category | C8: A | G8: CONVERSION COST | H8: =PROCESS!O2 -> 92.865526
B9: Date of estimation | C9: 14/6/2022 | G9: ICC | H9: =H7*C14 -> 3.2367388
B10: RM data base | C10: 44652 | G10: Rejection | H10: =C15*H7 -> 0.71927529
B11: Conversion data base | C11: 43466 | G11: Rejection | H11: =C16*H8 -> 0.92865526
G12: Tool maintenance | H12: =C17*H8 -> 1.8573105
B13: COST HEADS | G13: OH | H13: =C18*H8 -> 13.929829
B14: ICC | C14: 0.0225 | D14: RM | G14: Profit | H14: =(H7+H8)*C19 -> 18.937647
B15: Rejection | C15: 0.005 | D15: RM | G15: OTEHR COST | H15: =SUM(H9:H14) -> 39.609456
B16: Rejection | C16: 0.01 | D16: Conv | G16: TOTAL COST | H16: =SUM(H8:H14)+H7 -> 276.33004 | I16: =H16/H17 -> 706.72645
B17: Tool maintenance | C17: 0.02 | D17: Conv | G17: Total Finish weight(kg) | H17: =MATERIAL!K16 -> 0.391
B18: OH | C18: =IF(C8="A",15%,IF(C8="B",12%,10%)) -> 0.15 | D18: Conv
B19: Profit | C19: =IF(C8="A",8%,IF(C8="B",6%,5%)) -> 0.08 | D19: RM+Conv | G19: KEY RATIOS | H19: %
G20: RM Cost / Total Cost | H20: =H7/H16 -> 0.52059146
G21: Conversion cost / Total Cost | H21: =H8/H16 -> 0.33606743
G22: Other cost/ Total Cost | H22: =H15/H16 -> 0.14334111

Sheet MATERIAL
A11: Material | G11: Hindalco | Q11: Melting Cost | R11: 5 | S11: Per Kg | Y11: RM | Z11: =SUMIF($D$14:$D$1048576,$Y11,$Z$14:$Z$81) -> 143.85506
K12: Model weight | M12: Provided Design | N12: 10% of Casting weight | P12: Back-up | T12: Re-used for melting | W12: Provided Design | X12: Shell Core | Y12: BOP | Z12: =Z15 -> 0 | AB12: =SUM(AB14:AB1048576) -> 113.39 | AC12: =SUM(AC14:AC1048576) -> 30.465058
A13: Sl No | B13: Item description | C13: Part Number | D13: RM/ BOP | E13: Qty | F13: Grade | G13: Price/ kg | H13: Length (mm) | I13: Width (mm) | J13: Part Thickness (mm) | K13: Net Weight (kg) | L13: Machining Allowance | M13: Cast Weight | N13: Others - Gate / Runner / Filler | O13: Melt weight (kg) | P13: Surcharge/ Burning loss | Q13: Surcharge/ Burning loss Cost | R13: RM Price | S13: Scrap(kg) | T13: Scrap price/kg | U13: Scrap realisation % | V13: Scrap price | W13: Total core Wt. (Kg) | X13: Core Cost | Y13: Price / unit | Z13: Total Price | AA13: Remarks | AB13: Direct RM | AC13: All RM
A14: 1 | B14: Piston head | C14: FXB01800_Assy02_Item05 | D14: RM | E14: 1 | F14: LM25 | G14: =VLOOKUP(F14,'RM database'!A:B,2,0) -> 290 | K14: 0.391 | L14: =C38 -> 0.16385219 | M14: =K14+L14 -> 0.55485219 | N14: =M14*10% -> 0.055485219 | O14: =N14+M14 -> 0.61033741 | P14: 0.08 | Q14: =O14*P14*(G14) -> 14.159828 | R14: =O14*G14+Q14 -> 191.15768 | S14: =O14-K14 -> 0.21933741 | T14: =G14 -> 290 | U14: 0.8 | V14: =U14*S14*T14 -> 50.886278 | W14: =C20 -> 0.39328594 | X14: =E29 -> 3.5836608 | Y14: =R14+X14-V14 -> 143.85506 | Z14: =Y14*E14 -> 143.85506 | AB14: =K14*G14 -> 113.39 | AC14: =Z14-AB14 -> 30.465058
K16: =SUM(K14:K15) -> 0.391
B17: Core wt calculation
B18: Core volume | C18: =3.14/4*47^2*120/10^9 -> 0.0002080878 | D18: m3
B19: Core density | C19: 1800 | D19: kg/m3
B20: Core weight | C20: =C18*C19*1.05 -> 0.39328594 | D20: kg/m3
C23: Consumption per Kg of Core | D23: Price/kg | E23: Component price
B24: Washed new sand | C24: =100%-C25-C26-C27 -> 0.973 | D24: 5.7 | E24: =C24*D24*$C$20 -> 2.1812032
B25: Resin A | C25: =1.1% -> 0.011 | D25: 73 | E25: =C25*D25*$C$20 -> 0.31580861
B26: Resin B | C26: =1.1% -> 0.011 | D26: 145 | E26: =C26*D26*$C$20 -> 0.62729108
B27: Amine Gas | C27: =0.5% -> 0.005 | D27: 140 | E27: =C27*D27*$C$20 -> 0.27530016
B28: Special sundry material | C28: =1.8% -> 0.018 | D28: 26 | E28: =C28*D28*$C$20 -> 0.18405782
B29: Total RM Cost for Core | E29: =SUM(E24:E28) -> 3.5836608
B31: Machining Calculation
B33: OD machining Scrap weight | C33: =3.14*55*75*2*2700/10^9 -> 0.0699435 | D33: kg
B34: Top face machining | C34: =3.14/4*55^2*2*2700/10^9*2 -> 0.02564595 | D34: kg
B35: Drill dia 23mm for length of 43mm | C35: =3.14/4*23^2*43*2700/10^9 -> 0.048212267 | D35: kg
B36: Counter sunk | C36: =3.14/4*15^2*12*2700/10^9 -> 0.00572265 | D36: kg
B37: Pin mounting hole | C37: =3.14/4*13^2*40*2700/10^9 -> 0.01432782 | D37: kg
C38: =SUM(C33:C37) -> 0.16385219

Sheet PROCESS
A1: PROCESS
M2: =SUM(M5:M26) -> 92.865526 | O2: =SUM(O5:O115) -> 92.865526
A3: S NO | B3: ITEM DESCRIPTION | C3: PROCESS DESCRIPTION | D3: QTY | F3: MACHINERY COST | O3: TOTAL VALUE ADD | P3: REMARKS
F4: Operation | G4: SC1 | H4: Norms Rs/Unit | I4: UOM | J4: Units | K4: Time in Sec | L4: Parts Per unit | M4: Cost/part
A5: A | B5: Casting | C5: Aluminium GDC conversion | D5: 1 | F5: GDC | G5: < 2 kg | H5: 82 | I5: per kg | J5: =MATERIAL!O14 -> 0.61033741 | M5: =H5*J5 -> 50.047667 | O5: =M5*D5 -> 50.047667
A6: C | C6: Shot blasting | D6: 1 | F6: Shot blasting | H6: 7 | I6: per kg | J6: =MATERIAL!M14 -> 0.55485219 | M6: =H6*J6 -> 3.8839653 | O6: =M6*D6 -> 3.8839653
A7: D | C7: Impregnation | D7: 1 | F7: Impregnation | H7: 15 | I7: per kg | J7: =J6 -> 0.55485219 | M7: =H7*J7 -> 8.3227828 | O7: =M7*D7 -> 8.3227828
A8: F | C8: Cleaning | D8: 1 | F8: Cleaning | G8: Approx | H8: 5 | I8: per part | J8: 1 | M8: =H8*J8 -> 5 | O8: =M8*D8 -> 5
A9: 1 | B9: Machining | C9: Loading to the machine | D9: 1 | F9: CNC Turning machine | H9: 300 | I9: per hr | K9: 15 | L9: 1 | M9: =H9/3600*K9 -> 1.25 | O9: =M9*D9 -> 1.25
A10: 2 | C10: Facing operation | D10: 1 | F10: CNC Turning machine | H10: 300 | I10: per hr | K10: 15 | L10: 1 | M10: =H10/3600*K10 -> 1.25 | O10: =M10*D10 -> 1.25
A11: 3 | C11: Step turning operation | D11: 1 | F11: CNC Turning machine | H11: 300 | I11: per hr | K11: 40 | L11: 1 | M11: =H11/3600*K11 -> 3.3333333 | O11: =M11*D11 -> 3.3333333
A12: 5 | C12: Pilot drilling operation | D12: 1 | F12: CNC Turning machine | H12: 300 | I12: per hr | K12: 25 | L12: 1 | M12: =H12/3600*K12 -> 2.0833333 | O12: =M12*D12 -> 2.0833333
A13: 6 | C13: Drilling operation | D13: 1 | F13: CNC Turning machine | H13: 300 | I13: per hr | K13: 25 | L13: 1 | M13: =H13/3600*K13 -> 2.0833333 | O13: =M13*D13 -> 2.0833333
A14: 3 | C14: Counter sunk operation | D14: 1 | F14: CNC Turning machine | H14: 300 | I14: per hr | K14: 15 | L14: 1 | M14: =H14/3600*K14 -> 1.25 | O14: =M14*D14 -> 1.25
A15: 3 | C15: Through hole | D15: 1 | F15: CNC Turning machine | H15: 300 | I15: per hr | K15: 10 | L15: 1 | M15: =H15/3600*K15 -> 0.83333333 | O15: =M15*D15 -> 0.83333333
C16: Chamfering operation | D16: 1 | F16: CNC Turning machine | H16: 300 | I16: per hr | K16: 15 | L16: 1 | M16: =H16/3600*K16 -> 1.25 | O16: =M16*D16 -> 1.25
A17: 7 | C17: Unloading from the machine | D17: 1 | F17: CNC Turning machine | H17: 300 | I17: per hr | K17: 15 | L17: 1 | M17: =H17/3600*K17 -> 1.25 | O17: =M17*D17 -> 1.25
A18: 3 | C18: Loading to the machine | D18: 1 | F18: CNC Turning machine | H18: 300 | I18: per hr | K18: 15 | L18: 1 | M18: =H18/3600*K18 -> 1.25 | O18: =M18*D18 -> 1.25
A19: 2 | C19: Facing operation | D19: 1 | F19: CNC Turning machine | H19: 300 | I19: per hr | K19: 15 | L19: 1 | M19: =H19/3600*K19 -> 1.25 | O19: =M19*D19 -> 1.25
A20: 3 | C20: Step turning operation | D20: 1 | F20: CNC Turning machine | H20: 300 | I20: per hr | K20: 40 | L20: 1 | M20: =H20/3600*K20 -> 3.3333333 | O20: =M20*D20 -> 3.3333333
A21: 3 | C21: Unloading from the machine | D21: 1 | F21: CNC Turning machine | H21: 300 | I21: per hr | K21: 15 | L21: 1 | M21: =H21/3600*K21 -> 1.25 | O21: =M21*D21 -> 1.25
A22: 5 | C22: Loading to the machine | D22: 1 | F22: Drill machine | H22: 100 | I22: per hr | K22: 20 | L22: 1 | M22: =H22/3600*K22 -> 0.55555556 | O22: =M22*D22 -> 0.55555556
A23: 6 | C23: Drilling operation | D23: 1 | F23: Drill machine | H23: 100 | I23: per hr | K23: 30 | L23: 1 | M23: =H23/3600*K23 -> 0.83333333 | O23: =M23*D23 -> 0.83333333
A24: 5 | C24: unloading from the machine | D24: 1 | F24: Drill machine | H24: 100 | I24: per hr | K24: 20 | L24: 1 | M24: =H24/3600*K24 -> 0.55555556 | O24: =M24*D24 -> 0.55555556
A25: 24 | C25: Dressing | D25: 1 | F25: Manual Process | M25: 1 | O25: =M25*D25 -> 1
A26: 25 | C26: Packing, Storage& Despatch | D26: 1 | F26: Manual Process | M26: 1 | O26: =M26*D26 -> 1
B29: 2/kg on casting wt | C29: Shot blasting | F29: Drilling
B30: 7/kg on cast wt | C30: Impregnation | F30: Ø | G30: Depth | H30: CS | I30: RPM | J30: Feed mm/rev | K30: Time
B31: 5 | C31: Leak test | F31: 14.5 | G31: 25 | H31: 120 | I31: =H31*1000/(PI()*F31) -> 2634.2887 | J31: 0.05 | K31: =(G31+12)/(I31*J31/60)+5 -> 21.854645
B32: 5 | C32: Cleaning
F33: Milling
F34: Cutter Ø | G34: Length | H34: Width | I34: No of pass | J34: No of insert | K34: CS | L34: RPM | M34: Feed mm/rev | N34: Time
F35: 40 | G35: 30 | H35: 35 | I35: 1 | J35: 3 | K35: 600 | L35: =K35*1000/(PI()*F35) -> 4774.6483 | M35: =0.1*J35 -> 0.3 | N35: =((G35+(F35+10)+IF(H35<F35,0,((CEILING(H35/F35,1)-1)*G35)+((CEILING(H35/F35,1)-1)*F35)))/(M35*L35/60)+5)*I35 -> 8.3510322
F38: 5 seconds considered for rapid movement
F39: 5 seconds considered for centre drilling
F40: Cutting speed for Aluminium considered is 300m/min for carbide inserts and 150m/min for HSS tools
F42: Drilling Tool Life
F43: Material | G43: Nearest drill size | H43: Hole depth | I43: No of holes
F44: SG iron/Casting | G44: 20 | H44: 100 | I44: =IF(F44=0, ,VLOOKUP(TRUE,'Tool Life'!$A:$F,IF(PROCESS!F44='Tool Life'!E1,5,6),0)) -> 400
F46: Milling insert Life
...

Sheet RM database
A2: Grade | B2: Price/ kg
A3: LM25 | B3: 290 | C3: Apr'22 | D3: Sourcing input

Sheet Tool Life
B1: Drill - HSS | E1: Carbon Steel | F1: SG iron/Casting | I1: Life for 10 mm
B2: Sl. No. | C2: Drill Ø | D2: Length | E2: No holes | F2: No holes | G2: Remarks | I2: Carbon steel | J2: SG iron/Casting
A3: =C3=[5]PROCESS!$G$47 -> FALSE | B3: 1 | C3: 5 | D3: =[5]PROCESS!$H$47 -> 100 | E3: =IF(D3<=10,I3,IF(D3>100,I3/100*10,(I3/D3*10))) -> 200 | F3: =IF(D3<=10,J3,IF(D3>100,J3/100*10,(J3/D3*10))) -> 360 | G3: Direct | I3: 2000 | J3: =I3*1.8 -> 3600
A4: =C4=[5]PROCESS!$G$47 -> FALSE | B4: 2 | C4: 7.5 | D4: =[5]PROCESS!$H$47 -> 100 | E4: =IF(D4<=10,I4,IF(D4>100,I4/100*10,(I4/D4*10))) -> 180 | F4: =IF(D4<=10,J4,IF(D4>100,J4/100*10,(J4/D4*10))) -> 324 | G4: Direct | I4: 1800 | J4: =I4*1.8 -> 3240
A5: =C5=[5]PROCESS!$G$47 -> FALSE | B5: 3 | C5: 10 | D5: =[5]PROCESS!$H$47 -> 100 | E5: =IF(D5<=10,I5,IF(D5>100,I5/100*10,(I5/D5*10))) -> 170 | F5: =IF(D5<=10,J5,IF(D5>100,J5/100*10,(J5/D5*10))) -> 306 | G5: Direct | I5: 1700 | J5: =I5*1.8 -> 3060
A6: =C6=[5]PROCESS!$G$47 -> FALSE | B6: 4 | C6: 12.5 | D6: =[5]PROCESS!$H$47 -> 100 | E6: =IF(D6<=10,I6,IF(D6>100,I6/100*10,(I6/D6*10))) -> 160 | F6: =IF(D6<=10,J6,IF(D6>100,J6/100*10,(J6/D6*10))) -> 288 | G6: Direct | I6: 1600 | J6: =I6*1.8 -> 2880
A7: =C7=[5]PROCESS!$G$47 -> FALSE | B7: 5 | C7: 15 | D7: =[5]PROCESS!$H$47 -> 100 | E7: =IF(D7<=10,I7,IF(D7>100,I7/100*10,(I7/D7*10))) -> 200 | F7: =IF(D7<=10,J7,IF(D7>100,J7/100*10,(J7/D7*10))) -> 400 | G7: With pre-drill | I7: 2000 | J7: =I7*2 -> 4000
A8: =C8=[5]PROCESS!$G$47 -> FALSE | B8: 6 | C8: 17.5 | D8: =[5]PROCESS!$H$47 -> 100 | E8: =IF(D8<=10,I8,IF(D8>100,I8/100*10,(I8/D8*10))) -> 200 | F8: =IF(D8<=10,J8,IF(D8>100,J8/100*10,(J8/D8*10))) -> 400 | G8: With pre-drill | I8: 2000 | J8: =I8*2 -> 4000
A9: =C9=[5]PROCESS!$G$47 -> TRUE | B9: 7 | C9: 20 | D9: =[5]PROCESS!$H$47 -> 100 | E9: =IF(D9<=10,I9,IF(D9>100,I9/100*10,(I9/D9*10))) -> 200 | F9: =IF(D9<=10,J9,IF(D9>100,J9/100*10,(J9/D9*10))) -> 400 | G9: With pre-drill | I9: 2000 | J9: =I9*2 -> 4000
A10: =C10=[5]PROCESS!$G$47 -> FALSE | B10: 8 | C10: 22.5 | D10: =[5]PROCESS!$H$47 -> 100 | E10: =IF(D10<=10,I10,IF(D10>100,I10/100*10,(I10/D10*10))) -> 225 | F10: =IF(D10<=10,J10,IF(D10>100,J10/100*10,(J10/D10*10))) -> 450 | G10: With pre-drill | I10: 2250 | J10: =I10*2 -> 4500
A11: =C11=[5]PROCESS!$G$47 -> FALSE | B11: 9 | C11: 25 | D11: =[5]PROCESS!$H$47 -> 100 | E11: =IF(D11<=10,I11,IF(D11>100,I11/100*10,(I11/D11*10))) -> 225 | F11: =IF(D11<=10,J11,IF(D11>100,J11/100*10,(J11/D11*10))) -> 450 | G11: With pre-drill | I11: 2250 | J11: =I11*2 -> 4500
A12: =C12=[5]PROCESS!$G$47 -> FALSE | B12: 10 | C12: 27.5 | D12: =[5]PROCESS!$H$47 -> 100 | E12: =IF(D12<=10,I12,IF(D12>100,I12/100*10,(I12/D12*10))) -> 225 | F12: =IF(D12<=10,J12,IF(D12>100,J12/100*10,(J12/D12*10))) -> 450 | G12: With pre-drill | I12: 2250 | J12: =I12*2 -> 4500
A13: =C13=[5]PROCESS!$G$47 -> FALSE | B13: 11 | C13: 30 | D13: =[5]PROCESS!$H$47 -> 100 | E13: =IF(D13<=10,I13,IF(D13>100,I13/100*10,(I13/D13*10))) -> 250 | F13: =IF(D13<=10,J13,IF(D13>100,J13/100*10,(J13/D13*10))) -> 500 | G13: With pre-drill | I13: 2500 | J13: =I13*2 -> 5000
A14: =C14=[5]PROCESS!$G$47 -> FALSE | B14: 12 | C14: 32.5 | D14: =[5]PROCESS!$H$47 -> 100 | E14: =IF(D14<=10,I14,IF(D14>100,I14/100*10,(I14/D14*10))) -> 250 | F14: =IF(D14<=10,J14,IF(D14>100,J14/100*10,(J14/D14*10))) -> 500 | G14: With pre-drill | I14: 2500 | J14: =I14*2 -> 5000
A15: =C15=[5]PROCESS!$G$47 -> FALSE | B15: 13 | C15: 35 | D15: =[5]PROCESS!$H$47 -> 100 | E15: =IF(D15<=10,I15,IF(D15>100,I15/100*10,(I15/D15*10))) -> 300 | F15: =IF(D15<=10,J15,IF(D15>100,J15/100*10,(J15/D15*10))) -> 660 | G15: With pre-drill | I15: 3000 | J15: =I15*2.2 -> 6600
A16: =C16=[5]PROCESS!$G$47 -> FALSE | B16: 14 | C16: 37.5 | D16: =[5]PROCESS!$H$47 -> 100 | E16: =IF(D16<=10,I16,IF(D16>100,I16/100*10,(I16/D16*10))) -> 300 | F16: =IF(D16<=10,J16,IF(D16>100,J16/100*10,(J16/D16*10))) -> 660 | G16: With pre-drill | I16: 3000 | J16: =I16*2.2 -> 6600
A17: =C17=[5]PROCESS!$G$47 -> FALSE | B17: 15 | C17: 40 | D17: =[5]PROCESS!$H$47 -> 100 | E17: =IF(D17<=10,I17,IF(D17>100,I17/100*10,(I17/D17*10))) -> 350 | F17: =IF(D17<=10,J17,IF(D17>100,J17/100*10,(J17/D17*10))) -> 770 | G17: With pre-drill | I17: 3500 | J17: =I17*2.2 -> 7700
A18: =C18=[5]PROCESS!$G$47 -> FALSE | B18: 16 | C18: 42.5 | D18: =[5]PROCESS!$H$47 -> 100 | E18: =IF(D18<=10,I18,IF(D18>100,I18/100*10,(I18/D18*10))) -> 350 | F18: =IF(D18<=10,J18,IF(D18>100,J18/100*10,(J18/D18*10))) -> 770 | G18: With pre-drill | I18: 3500 | J18: =I18*2.2 -> 7700
A19: =C19=[5]PROCESS!$G$47 -> FALSE | B19: 17 | C19: 45 | D19: =[5]PROCESS!$H$47 -> 100 | E19: =IF(D19<=10,I19,IF(D19>100,I19/100*10,(I19/D19*10))) -> 400 | F19: =IF(D19<=10,J19,IF(D19>100,J19/100*10,(J19/D19*10))) -> 880 | G19: With pre-drill | I19: 4000 | J19: =I19*2.2 -> 8800
A20: =C20=[5]PROCESS!$G$47 -> FALSE | B20: 18 | C20: 47.5 | D20: =[5]PROCESS!$H$47 -> 100 | E20: =IF(D20<=10,I20,IF(D20>100,I20/100*10,(I20/D20*10))) -> 400 | F20: =IF(D20<=10,J20,IF(D20>100,J20/100*10,(J20/D20*10))) -> 880 | G20: With pre-drill | I20: 4000 | J20: =I20*2.2 -> 8800
A21: =C21=[5]PROCESS!$G$47 -> FALSE | B21: 19 | C21: 50 | D21: =[5]PROCESS!$H$47 -> 100 | E21: =IF(D21<=10,I21,IF(D21>100,I21/100*10,(I21/D21*10))) -> 400 | F21: =IF(D21<=10,J21,IF(D21>100,J21/100*10,(J21/D21*10))) -> 880 | G21: With pre-drill | I21: 4000 | J21: =I21*2.2 -> 8800
B24: Carbide insert - Milling | I24: Milled material volume with one insert in mm^3
E25: Carbon steel | F25: SG Iron/Casting | I25: Carbon Steel | J25: SG Iron/Casting
B26: ~ Mill Area (mm^2) | C26: Depth of cut (mm) | D26: No of inserts | E26: Tool use count | F26: Tool use count | I26: Volume of material removal mm^3 | J26: Volume of material removal mm^3 | K26: Remarks
B27: =[5]PROCESS!G51 -> 38550 | C27: 3 | D27: =[5]PROCESS!H51 -> 6 | E27: =I27/B27*C27*D27 -> 466.92607 | F27: =J27/B27*C27*D27 -> 583.65759 | I27: 1000000 | J27: 1250000 | K27: Two tip usage considered for a insert

Sheet Machinery
B1: SR.NO | C1: Domain | D1: MACHINERY | E1: PURCHASE COST | F1: MAINTAINENCE COST | G1: POWER (KW) | H1: Power Factor | I1: AUXILIARY EQUIPMENT | J1: FLOOR SPACE (M2) | K1: EFFICIENCY/OEE | L1: DEPRECIATION PERIOD | M1: CAPITAL COST | N1: FIXED COST | O1: NET MACHINE TIME | P1: VARIABLE COST | Q1: MMR | R1: MHR
B2: 1 | C2: Casting | D2: Oil Furnace | E2: 10000000 | F2: 121500 | G2: 33 | H2: 0.7 | I2: 9647058.8 | J2: 10 | K2: 0.85 | L2: 10 | M2: 1600000 | N2: 323158.2 | O2: 6120 | P2: 25699167 | Q2: 75.224198 | R2: 4513.4519
B3: 2 | C3: Casting | D3: Melting furnace (1.5 t) | E3: 10000000 | F3: 499344 | G3: 150 | I3: 14715619 | J3: 30 | K3: 0.85 | L3: 10 | M3: 1600000 | N3: 1313326.8 | O3: 6120 | P3: 37524829 | Q3: 110.1257 | R3: 6607.5418
B4: 3 | C4: Casting | D4: Holding furnace (0.5 t) | E4: 1000000 | F4: 100000 | G4: 40 | I4: 13332 | J4: 5 | K4: 0.85 | L4: 10 | M4: 160000 | N4: 261666.6 | O4: 6120 | P4: 33996.6 | Q4: 1.2409129 | R4: 74.454771
B5: 4 | C5: Casting | D5: Induction Furnace Metal Melting 8T | E5: 40000000 | F5: 2000000 | G5: 3300 | H5: 0.7 | I5: 800000 | J5: 50 | K5: 0.85 | L5: 10 | M5: 6400000 | N5: 5166666 | O5: 6120 | P5: 1.1195673e+08 | Q5: 336.39269 | R5: 20183.561
B6: 5 | C6: Casting | D6: Induction Furnace Metal Melting 1T | E6: 6500000 | F6: 650000 | G6: 550 | H6: 0.7 | I6: 130000 | J6: 10 | K6: 0.85 | L6: 10 | M6: 1040000 | N6: 1670833.2 | O6: 6120 | P6: 18650955 | Q6: 58.174804 | R6: 3490.4883
B7: 6 | C7: Casting | D7: Core Shooter | E7: 4000000 | F7: 160000 | G7: 15 | H7: 0.7 | I7: 80000 | J7: 20 | K7: 0.85 | L7: 10 | M7: 640000 | N7: 434666.4 | O7: 6120 | P7: 703621.5 | Q7: 4.842832 | R7: 290.56992
B8: 7 | C8: Casting | D8: Core Preparation Manual | E8: 200000 | F8: 8000 | G8: 0 | H8: 0.7 | I8: 4000 | J8: 5 | K8: 0.85 | L8: 10 | M8: 32000 | N8: 27066.6 | O8: 6120 | P8: 10200 | Q8: 0.18863453 | R8: 11.318072
B9: 8 | C9: Casting | D9: Core Sand Mixing | E9: 1000000 | F9: 40000 | G9: 5 | H9: 0.7 | I9: 20000 | J9: 15 | K9: 0.85 | L9: 10 | M9: 160000 | N9: 121999.8 | O9: 6120 | P9: 217540.5 | Q9: 1.3604039 | R9: 81.624232
B10: 9 | C10: Casting | D10: Core Heating | E10: 1000000 | F10: 40000 | G10: 10 | H10: 0.7 | I10: 20000 | J10: 10 | K10: 0.85 | L10: 10 | M10: 160000 | N10: 115333.2 | O10: 6120 | P10: 384081 | Q10: 1.7957903 | R10: 107.74742
B11: 10 | C11: Casting | D11: Core Painting | E11: 500000 | F11: 20000 | G11: 3 | H11: 0.7 | I11: 10000 | J11: 5 | K11: 0.85 | L11: 10 | M11: 80000 | N11: 57666.6 | O11: 6120 | P11: 125424.3 | Q11: 0.71647849 | R11: 42.988709
B12: 11 | C12: Casting | D12: Shell Core Machine | E12: 3000000 | F12: 120000 | G12: 15 | H12: 0.7 | I12: 60000 | J12: 10 | K12: 0.85 | L12: 10 | M12: 480000 | N12: 319333.2 | O12: 6120 | P12: 652621.5 | Q12: 3.954125 | R12: 237.2475
B13: 12 | C13: Casting | D13: Mould sand Preparation | E13: 4000000 | F13: 160000 | G13: 10 | H13: 0.7 | I13: 80000 | J13: 30 | K13: 0.85 | L13: 10 | M13: 640000 | N13: 447999.6 | O13: 6120 | P13: 537081 | Q13: 4.4256008 | R13: 265.53605
B14: 13 | C14: Casting | D14: Mould Preparation | E14: 5000000 | F14: 200000 | G14: 15 | H14: 0.7 | I14: 100000 | J14: 20 | K14: 0.85 | L14: 10 | M14: 800000 | N14: 536666.4 | O14: 6120 | P14: 754621.5 | Q14: 5.6952285 | R14: 341.71371
B15: 14 | C15: Casting | D15: Casting | E15: 1000000 | F15: 40000 | G15: 0 | H15: 0.7 | I15: 20000 | J15: 20 | K15: 0.85 | L15: 10 | M15: 160000 | N15: 128666.4 | O15: 6120 | P15: 51000 | Q15: 0.92501743 | R15: 55.501046
B16: 15 | C16: Casting | D16: Fetling | E16: 1000000 | F16: 40000 | G16: 10 | H16: 0.7 | I16: 20000 | J16: 20 | K16: 0.85 | L16: 10 | M16: 160000 | N16: 128666.4 | O16: 6120 | P16: 384081 | Q16: 1.8321008 | R16: 109.92605
... B25: 24 | C25: Finishing | D25: Grinding machine | E25: 800000 | F25: 40000 | G25: 20 | H25: 0.4 | I25: 16000 | J25: 25 | K25: 0.85 | L25: 10 | M25: 128000 | N25: 135333 | O25: 6120 | P25: 421464 | Q25: 1.8649156 | R25: 111.89493
B26: 25 | C26: Finishing | D26: Grinding - surface | E26: 2880000 | F26: 52000 | G26: 10 | I26: 79200000 | J26: 4 | K26: 0.85 | L26: 10 | M26: 460800 | N26: 137933.28 | O26: 6120 | P26: 201960000 | Q26: 551.63054 | R26: 33097.832
B27: 26 | C27: Finishing | D27: Surface Grinding Machine | E27: 1300000 | F27: 65000 | G27: 7.5 | H27: 0.7 | I27: 50000 | J27: 10 | K27: 0.85 | L27: 10 | M27: 208000 | N27: 179083.2 | O27: 6120 | P27: 377310.75 | Q27: 2.0816829 | R27: 124.90097
B28: 27 | C28: Finishing | D28: Grinding m/c- centreless | E28: 2000000 | F28: 60000 | G28: 5 | H28: 0.7 | I28: 350000 | J28: 4 | K28: 0.85 | L28: 10 | M28: 320000 | N28: 158333.28 | O28: 6120 | P28: 1059040.5 | Q28: 4.1867478 | R28: 251.20487
B29: 28 | C29: Finishing | D29: Centreless grinding | E29: 17000000 | F29: 850000 | G29: 25 | H29: 0.7 | I29: 340000 | J29: 15 | K29: 0.85 | L29: 10 | M29: 2720000 | N29: 2187499.8 | O29: 6120 | P29: 1699702.5 | Q29: 17.99347 | R29: 1079.6082
B30: 29 | C30: Finishing | D30: Belt Grinding machine | E30: 20000 | F30: 400 | G30: 2 | H30: 0.7 | I30: 400 | J30: 20 | K30: 0.85 | L30: 10 | M30: 3200 | N30: 27686.4 | O30: 6120 | P30: 67636.2 | Q30: 0.26830773 | R30: 16.098464
B31: 30 | C31: Finishing | D31: Hand buffing | E31: 5000 | F31: 250 | G31: 1 | H31: 0.7 | I31: 500 | J31: 10 | K31: 0.85 | L31: 10 | M31: 800 | N31: 13970.7 | O31: 6120 | P31: 34583.1 | Q31: 0.13440577 | R31: 8.0643464
B32: 31 | C32: Finishing | D32: Hand deburring | E32: 50000 | F32: 250 | G32: 0 | H32: 0.7 | I32: 500 | J32: 5 | K32: 0.85 | L32: 10 | M32: 8000 | N32: 7304.1 | O32: 6120 | P32: 1275 | Q32: 0.045150054 | R32: 2.7090033
B33: 32 | C33: Finishing | D33: Deburing m/c AMD01 | E33: 300000 | F33: 6000 | G33: 0.441 | I33: 6000 | J33: 1 | K33: 0.85 | L33: 10 | M33: 48000 | N33: 16633.32 | O33: 6120 | P33: 15300 | Q33: 0.21768333 | R33: 13.061
B34: 33 | C34: Finishing | D34: MKL AWH GRINDing m/c | E34: 1000000 | F34: 10000 | G34: 0.7 | I34: 5000 | J34: 15 | K34: 0.85 | L34: 10 | M34: 160000 | N34: 45499.8 | O34: 6120 | P34: 12750 | Q34: 0.5943622 | R34: 35.661732
B35: 34 | C35: Finishing | D35: Cylindrical grinder | E35: 1000000 | F35: 10000 | G35: 8.952 | I35: 50000 | J35: 6 | K35: 0.85 | L35: 10 | M35: 160000 | N35: 33499.92 | O35: 6120 | P35: 127500 | Q35: 0.87418279 | R35: 52.450967
B36: 35 | C36: Finishing | D36: Orbital grinders | E36: 76518914 | F36: 1530378.3 | G36: 11.25 | H36: 0.7 | I36: 765189.14 | J36: 20 | K36: 0.85 | L36: 10 | M36: 12243026 | N36: 3929131 | O36: 6120 | P36: 2325948.4 | Q36: 50.376105 | R36: 3022.5663
B37: 36 | C37: Finishing | D37: Lapping M/c | E37: 1000000 | F37: 10000 | G37: 25 | I37: 5000 | J37: 15 | K37: 0.85 | L37: 10 | M37: 160000 | N37: 45499.8 | O37: 6120 | P37: 12750 | Q37: 0.5943622 | R37: 35.661732
B38: 37 | C38: Finishing | D38: Superfinishing SPM | E38: 15000000 | F38: 600000 | G38: 11.25 | H38: 0.7 | I38: 300000 | J38: 10 | K38: 0.85 | L38: 10 | M38: 2400000 | N38: 1543333.2 | O38: 6120 | P38: 1139716.1 | Q38: 13.842727 | R38: 830.56362
B39: 38 | C39: Forging | D39: Forging Press | E39: 6480000 | F39: 162000 | G39: 10 | H39: 0.7 | I39: 16200 | J39: 20 | K39: 0.85 | L39: 10 | M39: 1036800 | N39: 439766.4 | O39: 6120 | P39: 374391 | Q39: 5.0407337 | R39: 302.44402
B40: 39 | C40: Forging | D40: Oil fired furnace | E40: 1000000 | F40: 50000 | G40: 100 | H40: 0.7 | I40: 20000 | J40: 25 | K40: 0.85 | L40: 10 | M40: 160000 | N40: 160833 | O40: 6120 | P40: 3381810 | Q40: 10.08345 | R40: 605.00703
B41: 40 | C41: Forging | D41: Press punching AMD01 | K41: 0.85 | L41: 10 | M41: 0 | N41: 0 | O41: 6120 | P41: 0 | Q41: 0.71666667 | R41: 43
B42: 41 | C42: Forging | D42: 3t-Forging Hammer | E42: 8000000 | F42: 80000 | G42: 74.6 | I42: 400000 | J42: 25 | K42: 0.85 | L42: 10 | M42: 1280000 | N42: 237333 | O42: 6120 | P42: 1020000 | Q42: 6.9099483 | R42: 414.5969
B43: 42 | C43: Forging | D43: 5t Hyd-Forging Hammer | E43: 5000000 | F43: 50000 | G43: 100 | H43: 0.7 | I43: 250000 | J43: 30 | K43: 0.85 | L43: 10 | M43: 800000 | N43: 167499.6 | O43: 6120 | P43: 3968310 | Q43: 13.441747 | R43: 806.50484
B44: 43 | C44: Forging | D44: 8t Hyd-Forging Hammer | E44: 8000000 | F44: 80000 | G44: 150 | H44: 0.7 | I44: 400000 | J44: 40 | K44: 0.85 | L44: 10 | M44: 1280000 | N44: 257332.8 | O44: 6120 | P44: 6016215 | Q44: 20.570664 | R44: 1234.2398
B45: 44 | C45: Forging | D45: 350T-Forging Press | E45: 9000000 | F45: 100000 | G45: 20 | H45: 0.7 | I45: 250000 | J45: 11 | K45: 0.85 | L45: 10 | M45: 1440000 | N45: 269666.52 | O45: 6120 | P45: 1303662 | Q45: 8.2062324 | R45: 492.37394
B46: 45 | C46: Forging | D46: 400T- High-Forging Press | E46: 35000000 | F46: 300000 | G46: 35 | H46: 0.7 | I46: 250000 | J46: 11 | K46: 0.85 | L46: 10 | M46: 5600000 | N46: 779666.52 | O46: 6120 | P46: 1803283.5 | Q46: 22.284722 | R46: 1337.0833
B47: 46 | C47: Forging | D47: 500 T-Forging Press | E47: 10623786 | K47: 0.85 | L47: 10 | M47: 1699805.8 | N47: 0 | O47: 6120 | P47: 0
B48: 47 | C48: Forging | D48: 750T-Forging Press | E48: 55000000 | F48: 550000 | G48: 60 | H48: 0.7 | I48: 350000 | J48: 15 | K48: 0.85 | L48: 10 | M48: 8800000 | N48: 1422499.8 | O48: 6120 | P48: 2890986 | Q48: 35.712107 | R48: 2142.7264
...

Sheet Sheet1
B2: Upto 1Kg = 30sec, 1-10Kg = 60sec, 10-40Kg = 120sec
B3: Cycle time = log((thickness/2),5)*140+10
B5: Tonnage = Cavity x (Area in sq mm/60)
B7: =1*173*173/60 -> 498.81667

Sheet Sheet2
A1: Supplier Name | B1: Qty 13-14 | C1: PO Value | D1: PO Price | F1: Qty 13-14 | G1: PO Value | H1: PO Price
A2: ASHLEY ALTEAMS INDIA LIMITED | B2: 250 | C2: 664560 | D2: =C2/B2 -> 2658.24 | E2: ASHLEY ALTEAMS INDIA LIMITED | F2: 150 | G2: 398736 | H2: =G2/F2 -> 2658.24
A3: ASHLEY ALTEAMS INDIA LIMITED | B3: 300 | C3: 797472 | D3: =C3/B3 -> 2658.24 | E3: ASHLEY ALTEAMS INDIA LIMITED | F3: 150 | G3: 5700 | H3: =G3/F3 -> 38
A4: ASHLEY ALTEAMS INDIA LIMITED | B4: 200 | C4: 531648 | D4: =C4/B4 -> 2658.24 | E4: ASHLEY ALTEAMS INDIA LIMITED | F4: 100 | G4: 265824 | H4: =G4/F4 -> 2658.24
A5: ASHLEY ALTEAMS INDIA LIMITED | B5: 50 | C5: 132912 | D5: =C5/B5 -> 2658.24 | E5: ASHLEY ALTEAMS INDIA LIMITED | F5: 100 | G5: 3800 | H5: =G5/F5 -> 38
A6: ASHLEY ALTEAMS INDIA LIMITED | B6: 250 | C6: 664560 | D6: =C6/B6 -> 2658.24 | E6: ASHLEY ALTEAMS INDIA LIMITED | F6: 100 | G6: 265824 | H6: =G6/F6 -> 2658.24
A7: ASHLEY ALTEAMS INDIA LIMITED | B7: 200 | C7: 531648 | D7: =C7/B7 -> 2658.24 | E7: ASHLEY ALTEAMS INDIA LIMITED | F7: 100 | G7: 3800 | H7: =G7/F7 -> 38
A8: ASHLEY ALTEAMS INDIA LIMITED | B8: 100 | C8: 265824 | D8: =C8/B8 -> 2658.24 | E8: ASHLEY ALTEAMS INDIA LIMITED | F8: 100 | G8: 265824 | H8: =G8/F8 -> 2658.24
A9: ASHLEY ALTEAMS INDIA LIMITED | B9: 100 | C9: 265824 | D9: =C9/B9 -> 2658.24 | E9: ASHLEY ALTEAMS INDIA LIMITED | F9: 100 | G9: 3800 | H9: =G9/F9 -> 38
A10: ASHLEY ALTEAMS INDIA LIMITED | B10: 100 | C10: 265824 | D10: =C10/B10 -> 2658.24 | E10: ASHLEY ALTEAMS INDIA LIMITED | F10: 150 | G10: 398736 | H10: =G10/F10 -> 2658.24
A11: ASHLEY ALTEAMS INDIA LIMITED | B11: 300 | C11: 797472 | D11: =C11/B11 -> 2658.24 | E11: ASHLEY ALTEAMS INDIA LIMITED | F11: 150 | G11: 5700 | H11: =G11/F11 -> 38
A12: ASHLEY ALTEAMS INDIA LIMITED | B12: 250 | C12: 664560 | D12: =C12/B12 -> 2658.24 | E12: ASHLEY ALTEAMS INDIA LIMITED | F12: 100 | G12: 265824 | H12: =G12/F12 -> 2658.24
A13: ASHLEY ALTEAMS INDIA LIMITED | B13: 300 | C13: 797472 | D13: =C13/B13 -> 2658.24 | E13: ASHLEY ALTEAMS INDIA LIMITED | F13: 100 | G13: 3800 | H13: =G13/F13 -> 38
... A97: JAYA HIND INDUSTRIES LIMITED | B97: 1 | C97: 3128 | D97: =C97/B97 -> 3128 | E97: ASHLEY ALTEAMS INDIA LIMITED | F97: 100 | G97: 3800 | H97: =G97/F97 -> 38
E98: ASHLEY ALTEAMS INDIA LIMITED | F98: 70 | G98: 186076.8 | H98: =G98/F98 -> 2658.24
E99: ASHLEY ALTEAMS INDIA LIMITED | F99: 70 | G99: 2660 | H99: =G99/F99 -> 38
E100: ASHLEY ALTEAMS INDIA LIMITED | F100: 100 | G100: 265824 | H100: =G100/F100 -> 2658.24
E101: ASHLEY ALTEAMS INDIA LIMITED | F101: 100 | G101: 3800 | H101: =G101/F101 -> 38
E102: ASHLEY ALTEAMS INDIA LIMITED | F102: 100 | G102: 265824 | H102: =G102/F102 -> 2658.24
E103: ASHLEY ALTEAMS INDIA LIMITED | F103: 100 | G103: 3800 | H103: =G103/F103 -> 38
E104: ASHLEY ALTEAMS INDIA LIMITED | F104: 100 | G104: 265824 | H104: =G104/F104 -> 2658.24
E105: ASHLEY ALTEAMS INDIA LIMITED | F105: 100 | G105: 3800 | H105: =G105/F105 -> 38
E106: ASHLEY ALTEAMS INDIA LIMITED | F106: 150 | G106: 398736 | H106: =G106/F106 -> 2658.24
E107: ASHLEY ALTEAMS INDIA LIMITED | F107: 150 | G107: 5700 | H107: =G107/F107 -> 38
E108: ASHLEY ALTEAMS INDIA LIMITED | F108: 100 | G108: 265824 | H108: =G108/F108 -> 2658.24
E109: ASHLEY ALTEAMS INDIA LIMITED | F109: 100 | G109: 3800 | H109: =G109/F109 -> 38
... E172: ASHLEY ALTEAMS INDIA LIMITED | F172: 100 | G172: 3800 | H172: =G172/F172 -> 38
