Workbook

Sheet Summary
A1: 1
B3: Component Details | F3: Database Details | G3: Database Details | K3: Estimation Details
B4: Part No | C4: =BOM!D3 -> FWR10000 | G4: RM Base | I4: 46028 | K4: Estimated on | M4: 46121
B5: Part Rev | C5: =BOM!E3 -> # | G5: Process Base | H5: 43466 | I5: 45954 | K5: Estimated by | M5: Sridhar S
B6: Descrtiption | C6: =BOM!F3 -> Seat - Driver Pneumatic Suspended | G6: OH, Profit & Other Base | H6: 44743 | I6: 44743 | K6: Part type
B8: Cost Head | C8: Direct RM Cost | D8: Allowance cost | E8: BOP cost | F8: Total RM cost | G8: Process Cost | H8: OH | I8: Profit | J8: Total Basic Cost | K8: Amortization | L8: Packing Cost | M8: Total Cost
B9: Amount
B10: Ratio | C10: =C9/$M$9 -> #DIV/0! | D10: =D9/$M$9 -> #DIV/0! | E10: =E9/$M$9 -> #DIV/0! | F10: =F9/$M$9 -> #DIV/0! | G10: =G9/$M$9 -> #DIV/0! | H10: =H9/$M$9 -> #DIV/0! | I10: =I9/$M$9 -> #DIV/0! | J10: =J9/$M$9 -> #DIV/0! | ... L10: =L9/$M$9 -> #DIV/0!
C13: Direct RM Cost | D13: Allowance cost | E13: BOP cost | F13: Total RM cost | G13: Process Cost | H13: OH | I13: Profit | J13: Total Basic Cost | K13: Amortization | L13: Packing Cost | M13: Total Cost
C14: =C9 -> 0 | D14: =C14 -> 0 | E14: =D14+D15 -> 0 | F14: =F9 -> 0 | G14: =F14 -> 0 | H14: =G14+G15 -> 0 | I14: =H14+H15 -> 0 | J14: =J9 -> 0 | K14: =J14 -> 0 | L14: =K14+K15 -> 0 | M14: =M9 -> 0
C15: 0 | D15: =D9 -> 0 | E15: =E9 -> 0 | G15: =G9 -> 0 | H15: =H9 -> 0 | I15: =I9 -> 0 | K15: =K9 -> 0 | L15: =L9 -> 0

Sheet BOM
A1: 1 | K1: =SUMPRODUCT(K3:K9999,$G3:$G9999) -> 5285.0334 | L1: =SUMPRODUCT(L3:L9999,$G3:$G9999) -> 224.59001 | M1: =SUMPRODUCT(M3:M9999,$G3:$G9999) -> 100.50216 | N1: =SUMPRODUCT(N3:N9999,$G3:$G9999) -> 59.82928 | O1: =SUMPRODUCT(O3:O9999,$G3:$G9999) -> 62.73469 | P1: =SUM(P3:P9999) -> 5180.9044 | Q1: =SUM(Q3:Q9999) -> 5732.6896 | T1: Total Weight | U1: =SUM(U3:U999999) -> 36.396 | AA1: =SUMPRODUCT(AA3:AA52,$G3:$G52) -> 224.59001 | AB1: =SUMPRODUCT(AB3:AB52,$G3:$G52) -> 8.68742 | AC1: =SUMPRODUCT(AC3:AC52,$G3:$G52) -> 0 | AD1: =SUMPRODUCT(AD3:AD52,$G3:$G52) -> 7.42932 | AE1: =SUMPRODUCT(AE3:AE52,$G3:$G52) -> 1.93053 | AF1: =SUMPRODUCT(AF3:AF52,$G3:$G52) -> 2.24589 | AG1: =SUMPRODUCT(AG3:AG52,$G3:$G52) -> 8.09347 | AH1: =SUMPRODUCT(AH3:AH52,$G3:$G52) -> 0 | ... AW1: =SUMPRODUCT(AW3:AW52,$G3:$G52) -> 100.50216 | AX1: =SUM(AX3:AX52) -> 5180.9044 | AY1: =SUM(AY3:AY52) -> 5732.6896
A2: S.no | B2: Parent part No. | C2: Level | D2: Part No. | E2: Rev | F2: Parts Description | G2: Qty | H2: Process Type | I2: Scope | J2: Method | K2: Material Cost | L2: Process Cost | M2: Surface finish cost Inhouse | N2: OH & Others | O2: Profit | P2: CPU | Q2: CPA | R2: CPSA | S2: Remarks | T2: Weight | U2: Total Weight | V2: Rate/kg | AA2: Process cost | AB2: ICC on RM | AC2: ICC on Conv | AD2: ICC on BOF | AE2: Rej on RM | AF2: Rej on Conv | AG2: Rej on BOF | AH2: Inspection on RM | AI2: Inspection on Conv | AJ2: Inspection on BOP | AK2: TMC on RM | AL2: TMC on Conv | AM2: TMC on BOF | AN2: Design cost on RM | AO2: Design cost on Conv | AP2: Design cost on BOP | AQ2: OH on RM | AR2: OH on Conv | AS2: OH on BOP | AT2: Profit on RM | AU2: Profit on Conv | AV2: Profit on BOP | AW2: Surface finish cost Inhouse | AX2: CPU | AY2: CPA
A3: 1 | B3: =D3 -> FWR10000 | C3: 1 | D3: FWR10000 | E3: # | F3: Seat - Driver Pneumatic Suspended | G3: 1 | H3: Assembly | I3: Inhouse | J3: CSC | K3: =_xlfn.IFNA(Backend!AN8,"") -> 0 | L3: =IFERROR(AA3,"") -> 0 | M3: =IFERROR(AW3,"") -> 0 | N3: =IF(SUM(AB3:AS3)=0,"",SUM(AB3:AS3)) | O3: =IF(SUM(AT3:AV3)=0,"",SUM(AT3:AV3)) | P3: =IF(K3="","",SUM(K3:O3)) -> 0 | Q3: =IF(P3="","",P3*G3) -> 0 | T3: =_xlfn.IFNA(IF(VLOOKUP(D3,Group!C:I,7,0)=0,"",VLOOKUP(D3,Group!C:I,7,0)),"") | U3: =IFERROR(T3*G3,"") | V3: =IFERROR(AY3/U3,"") | AA3: =_xlfn.IFNA(Backend!AO8,"") -> 0 | AB3: =Backend!AP8 -> 0 | AC3: =Backend!AQ8 -> 0 | AD3: =Backend!AR8 | AE3: =Backend!AS8 -> 0 | AF3: =Backend!AT8 -> 0 | AG3: =Backend!AU8 | AH3: =Backend!AV8 -> 0 | AI3: =Backend!AW8 -> 0 | ... AV3: =Backend!BJ8 | AW3: =_xlfn.IFNA(Backend!O8,"") -> 0 | AX3: =_xlfn.IFNA(IF(D3="","",Backend!BK8),"") -> 0 | AY3: =IF(AX3="","",AX3*G3) -> 0
A4: 2 | B4: =B3 -> FWR10000 | C4: 2 | D4: H 157 01 464 A | E4: 1 | F4: SLIDER KIT ASSY | G4: 1 | H4: Assembly | I4: Inhouse | J4: CSC | K4: =_xlfn.IFNA(Backend!AN9,"") -> 0 | L4: =IFERROR(AA4,"") -> 0 | M4: =IFERROR(AW4,"") -> 0 | N4: =IF(SUM(AB4:AS4)=0,"",SUM(AB4:AS4)) | O4: =IF(SUM(AT4:AV4)=0,"",SUM(AT4:AV4)) | P4: =IF(K4="","",SUM(K4:O4)) -> 0 | Q4: =IF(P4="","",P4*G4) -> 0 | T4: =_xlfn.IFNA(IF(VLOOKUP(D4,Group!C:I,7,0)=0,"",VLOOKUP(D4,Group!C:I,7,0)),"") | U4: =IFERROR(T4*G4,"") | V4: =IFERROR(AY4/U4,"") | AA4: =_xlfn.IFNA(Backend!AO9,"") -> 0 | AB4: =Backend!AP9 -> 0 | AC4: =Backend!AQ9 -> 0 | AD4: =Backend!AR9 | AE4: =Backend!AS9 -> 0 | AF4: =Backend!AT9 -> 0 | AG4: =Backend!AU9 | AH4: =Backend!AV9 -> 0 | AI4: =Backend!AW9 -> 0 | ... AV4: =Backend!BJ9 | AW4: =_xlfn.IFNA(Backend!O9,"") -> 0 | AX4: =_xlfn.IFNA(IF(D4="","",Backend!BK9),"") -> 0 | AY4: =IF(AX4="","",AX4*G4) -> 0
A5: 3 | B5: =B4 -> FWR10000 | C5: 3 | D5: H 157 01 464 A Top Mounting Brkt LH &RH | F5: Top Mounting Brkt LH &RH | G5: 2 | H5: Sheet Metal-B | I5: Inhouse | J5: CSC | K5: =_xlfn.IFNA(Backend!AN10,"") -> 52.18489 | L5: =IFERROR(AA5,"") -> 7.01506 | M5: =IFERROR(AW5,"") -> 10.30773 | N5: =IF(SUM(AB5:AS5)=0,"",SUM(AB5:AS5)) -> 2.48734 | O5: =IF(SUM(AT5:AV5)=0,"",SUM(AT5:AV5)) -> 3.55199 | P5: =IF(K5="","",SUM(K5:O5)) -> 75.54701 | Q5: =IF(P5="","",P5*G5) -> 151.09402 | T5: =_xlfn.IFNA(IF(VLOOKUP(D5,Group!C:I,7,0)=0,"",VLOOKUP(D5,Group!C:I,7,0)),"") -> 0.87 | U5: =IFERROR(T5*G5,"") -> 1.74 | V5: =IFERROR(AY5/U5,"") -> 86.835644 | AA5: =_xlfn.IFNA(Backend!AO10,"") -> 7.01506 | AB5: =Backend!AP10 -> 1.17416 | AC5: =Backend!AQ10 -> 0 | AD5: =Backend!AR10 | AE5: =Backend!AS10 -> 0.26092 | AF5: =Backend!AT10 -> 0.07015 | AG5: =Backend!AU10 | AH5: =Backend!AV10 -> 0 | AI5: =Backend!AW10 -> 0 | ... AV5: =Backend!BJ10 | AW5: =_xlfn.IFNA(Backend!O10,"") -> 10.30773 | AX5: =_xlfn.IFNA(IF(D5="","",Backend!BK10),"") -> 75.54701 | AY5: =IF(AX5="","",AX5*G5) -> 151.09402
A6: 4 | B6: =B5 -> FWR10000 | C6: 3 | D6: H 157 01 464 A M8 weld Nut | F6: M8 weld Nut | G6: 10 | H6: Sheet Metal-B | I6: BOF | J6: Standard | K6: =_xlfn.IFNA(Backend!AN11,"") -> 0.77 | L6: =IFERROR(AA6,"") | M6: =IFERROR(AW6,"") | N6: =IF(SUM(AB6:AS6)=0,"",SUM(AB6:AS6)) -> 0.0154 | O6: =IF(SUM(AT6:AV6)=0,"",SUM(AT6:AV6)) -> 0.0231 | P6: =IF(K6="","",SUM(K6:O6)) -> 0.8085 | Q6: =IF(P6="","",P6*G6) -> 8.085 | T6: =_xlfn.IFNA(IF(VLOOKUP(D6,Group!C:I,7,0)=0,"",VLOOKUP(D6,Group!C:I,7,0)),"") | U6: =IFERROR(T6*G6,"") | V6: =IFERROR(AY6/U6,"") | AA6: =_xlfn.IFNA(Backend!AO11,"") | AB6: =Backend!AP11 | AC6: =Backend!AQ11 | AD6: =Backend!AR11 -> 0.01155 | AE6: =Backend!AS11 | AF6: =Backend!AT11 | AG6: =Backend!AU11 -> 0.00385 | AH6: =Backend!AV11 | AI6: =Backend!AW11 | ... AV6: =Backend!BJ11 -> 0.0231 | AW6: =_xlfn.IFNA(Backend!O11,"") | AX6: =_xlfn.IFNA(IF(D6="","",Backend!BK11),"") -> 0.8085 | AY6: =IF(AX6="","",AX6*G6) -> 8.085
A7: 5 | B7: =B6 -> FWR10000 | C7: 3 | D7: H 157 01 464 A Rear Stopper LH &RH | F7: Rear Stopper LH &RH | G7: 2 | H7: Sheet Metal-B | I7: Inhouse | J7: CSC | K7: =_xlfn.IFNA(Backend!AN12,"") -> 3.66953 | L7: =IFERROR(AA7,"") -> 1.5933 | M7: =IFERROR(AW7,"") -> 1.19427 | N7: =IF(SUM(AB7:AS7)=0,"",SUM(AB7:AS7)) -> 0.33991 | O7: =IF(SUM(AT7:AV7)=0,"",SUM(AT7:AV7)) -> 0.31577 | P7: =IF(K7="","",SUM(K7:O7)) -> 7.11278 | Q7: =IF(P7="","",P7*G7) -> 14.22556 | T7: =_xlfn.IFNA(IF(VLOOKUP(D7,Group!C:I,7,0)=0,"",VLOOKUP(D7,Group!C:I,7,0)),"") -> 0.063 | U7: =IFERROR(T7*G7,"") -> 0.126 | V7: =IFERROR(AY7/U7,"") -> 112.90127 | AA7: =_xlfn.IFNA(Backend!AO12,"") -> 1.5933 | AB7: =Backend!AP12 -> 0.08256 | AC7: =Backend!AQ12 -> 0 | AD7: =Backend!AR12 | AE7: =Backend!AS12 -> 0.01835 | AF7: =Backend!AT12 -> 0.01593 | AG7: =Backend!AU12 | AH7: =Backend!AV12 -> 0 | AI7: =Backend!AW12 -> 0 | ... AV7: =Backend!BJ12 | AW7: =_xlfn.IFNA(Backend!O12,"") -> 1.19427 | AX7: =_xlfn.IFNA(IF(D7="","",Backend!BK12),"") -> 7.11278 | AY7: =IF(AX7="","",AX7*G7) -> 14.22556
A8: 6 | B8: =B7 -> FWR10000 | C8: 3 | D8: H 157 01 464 A Bottom MTG BRKT RH | F8: Bottom MTG BRKT RH | G8: 1 | H8: Sheet Metal-B | I8: Inhouse | J8: CSC | K8: =_xlfn.IFNA(Backend!AN13,"") -> 74.93066 | L8: =IFERROR(AA8,"") -> 11.78049 | M8: =IFERROR(AW8,"") -> 14.88104 | N8: =IF(SUM(AB8:AS8)=0,"",SUM(AB8:AS8)) -> 3.82766 | O8: =IF(SUM(AT8:AV8)=0,"",SUM(AT8:AV8)) -> 5.20267 | P8: =IF(K8="","",SUM(K8:O8)) -> 110.62252 | Q8: =IF(P8="","",P8*G8) -> 110.62252 | T8: =_xlfn.IFNA(IF(VLOOKUP(D8,Group!C:I,7,0)=0,"",VLOOKUP(D8,Group!C:I,7,0)),"") -> 1.256 | U8: =IFERROR(T8*G8,"") -> 1.256 | V8: =IFERROR(AY8/U8,"") -> 88.075255 | AA8: =_xlfn.IFNA(Backend!AO13,"") -> 11.78049 | AB8: =Backend!AP13 -> 1.68594 | AC8: =Backend!AQ13 -> 0 | AD8: =Backend!AR13 | AE8: =Backend!AS13 -> 0.37465 | AF8: =Backend!AT13 -> 0.1178 | AG8: =Backend!AU13 | AH8: =Backend!AV13 -> 0 | AI8: =Backend!AW13 -> 0 | ... AV8: =Backend!BJ13 | AW8: =_xlfn.IFNA(Backend!O13,"") -> 14.88104 | AX8: =_xlfn.IFNA(IF(D8="","",Backend!BK13),"") -> 110.62252 | AY8: =IF(AX8="","",AX8*G8) -> 110.62252
A9: 7 | B9: =B8 -> FWR10000 | C9: 3 | D9: H 157 01 464 A Bottom MTG BRKT REINF | F9: Bottom MTG BRKT REINF | G9: 2 | H9: Sheet Metal-B | I9: Inhouse | J9: CSC | K9: =_xlfn.IFNA(Backend!AN14,"") -> 3.32747 | L9: =IFERROR(AA9,"") -> 0.84451 | M9: =IFERROR(AW9,"") -> 0.41705 | N9: =IF(SUM(AB9:AS9)=0,"",SUM(AB9:AS9)) -> 0.21819 | O9: =IF(SUM(AT9:AV9)=0,"",SUM(AT9:AV9)) -> 0.25032 | P9: =IF(K9="","",SUM(K9:O9)) -> 5.05754 | Q9: =IF(P9="","",P9*G9) -> 10.11508 | T9: =_xlfn.IFNA(IF(VLOOKUP(D9,Group!C:I,7,0)=0,"",VLOOKUP(D9,Group!C:I,7,0)),"") -> 0.044 | U9: =IFERROR(T9*G9,"") -> 0.088 | V9: =IFERROR(AY9/U9,"") -> 114.94409 | AA9: =_xlfn.IFNA(Backend!AO14,"") -> 0.84451 | AB9: =Backend!AP14 -> 0.07487 | AC9: =Backend!AQ14 -> 0 | AD9: =Backend!AR14 | AE9: =Backend!AS14 -> 0.01664 | AF9: =Backend!AT14 -> 0.00845 | AG9: =Backend!AU14 | AH9: =Backend!AV14 -> 0 | AI9: =Backend!AW14 -> 0 | ... AV9: =Backend!BJ14 | AW9: =_xlfn.IFNA(Backend!O14,"") -> 0.41705 | AX9: =_xlfn.IFNA(IF(D9="","",Backend!BK14),"") -> 5.05754 | AY9: =IF(AX9="","",AX9*G9) -> 10.11508
A10: 8 | B10: =B9 -> FWR10000 | C10: 3 | D10: H 157 01 464 A Bottom MTG BRKT Spacer | F10: Bottom MTG BRKT Spacer | G10: 4 | H10: Sheet Metal-B | I10: Inhouse | J10: CSC | K10: =_xlfn.IFNA(Backend!AN15,"") -> 1.2423 | L10: =IFERROR(AA10,"") -> 15.13397 | M10: =IFERROR(AW10,"") -> 0.08846 | N10: =IF(SUM(AB10:AS10)=0,"",SUM(AB10:AS10)) -> 2.30426 | O10: =IF(SUM(AT10:AV10)=0,"",SUM(AT10:AV10)) -> 0.98258 | P10: =IF(K10="","",SUM(K10:O10)) -> 19.75157 | Q10: =IF(P10="","",P10*G10) -> 79.00628 | T10: =_xlfn.IFNA(IF(VLOOKUP(D10,Group!C:I,7,0)=0,"",VLOOKUP(D10,Group!C:I,7,0)),"") -> 0.014 | U10: =IFERROR(T10*G10,"") -> 0.056 | V10: =IFERROR(AY10/U10,"") -> 1410.8264 | AA10: =_xlfn.IFNA(Backend!AO15,"") -> 15.13397 | AB10: =Backend!AP15 -> 0.02795 | AC10: =Backend!AQ15 -> 0 | AD10: =Backend!AR15 | AE10: =Backend!AS15 -> 0.00621 | AF10: =Backend!AT15 -> 0.15134 | AG10: =Backend!AU15 | AH10: =Backend!AV15 -> 0 | AI10: =Backend!AW15 -> 0 | ... AV10: =Backend!BJ15 | AW10: =_xlfn.IFNA(Backend!O15,"") -> 0.08846 | AX10: =_xlfn.IFNA(IF(D10="","",Backend!BK15),"") -> 19.75157 | AY10: =IF(AX10="","",AX10*G10) -> 79.00628
A11: 9 | B11: =B10 -> FWR10000 | C11: 3 | D11: H 157 01 464 A Bottom MTG BRKT LH 1 | F11: Bottom MTG BRKT LH 1 | G11: 1 | H11: Sheet Metal-B | I11: Inhouse | J11: CSC | K11: =_xlfn.IFNA(Backend!AN16,"") -> 13.89634 | L11: =IFERROR(AA11,"") -> 7.33423 | M11: =IFERROR(AW11,"") -> 2.63025 | N11: =IF(SUM(AB11:AS11)=0,"",SUM(AB11:AS11)) -> 1.48228 | O11: =IF(SUM(AT11:AV11)=0,"",SUM(AT11:AV11)) -> 1.27383 | P11: =IF(K11="","",SUM(K11:O11)) -> 26.61693 | Q11: =IF(P11="","",P11*G11) -> 26.61693 | T11: =_xlfn.IFNA(IF(VLOOKUP(D11,Group!C:I,7,0)=0,"",VLOOKUP(D11,Group!C:I,7,0)),"") -> 0.222 | U11: =IFERROR(T11*G11,"") -> 0.222 | V11: =IFERROR(AY11/U11,"") -> 119.89608 | AA11: =_xlfn.IFNA(Backend!AO16,"") -> 7.33423 | AB11: =Backend!AP16 -> 0.31267 | AC11: =Backend!AQ16 -> 0 | AD11: =Backend!AR16 | AE11: =Backend!AS16 -> 0.06948 | AF11: =Backend!AT16 -> 0.07334 | AG11: =Backend!AU16 | AH11: =Backend!AV16 -> 0 | AI11: =Backend!AW16 -> 0 | ... AV11: =Backend!BJ16 | AW11: =_xlfn.IFNA(Backend!O16,"") -> 2.63025 | AX11: =_xlfn.IFNA(IF(D11="","",Backend!BK16),"") -> 26.61693 | AY11: =IF(AX11="","",AX11*G11) -> 26.61693
A12: 10 | B12: =B11 -> FWR10000 | C12: 3 | D12: H 157 01 464 A Bottom MTG BRKT LH 2 | F12: Bottom MTG BRKT LH 2 | G12: 1 | H12: Sheet Metal-B | I12: Inhouse | J12: CSC | K12: =_xlfn.IFNA(Backend!AN17,"") -> 16.69648 | L12: =IFERROR(AA12,"") -> 2.60869 | M12: =IFERROR(AW12,"") -> 3.31743 | N12: =IF(SUM(AB12:AS12)=0,"",SUM(AB12:AS12)) -> 0.85045 | O12: =IF(SUM(AT12:AV12)=0,"",SUM(AT12:AV12)) -> 1.15831 | P12: =IF(K12="","",SUM(K12:O12)) -> 24.63136 | Q12: =IF(P12="","",P12*G12) -> 24.63136 | T12: =_xlfn.IFNA(IF(VLOOKUP(D12,Group!C:I,7,0)=0,"",VLOOKUP(D12,Group!C:I,7,0)),"") -> 0.28 | U12: =IFERROR(T12*G12,"") -> 0.28 | V12: =IFERROR(AY12/U12,"") -> 87.969143 | AA12: =_xlfn.IFNA(Backend!AO17,"") -> 2.60869 | AB12: =Backend!AP17 -> 0.37567 | AC12: =Backend!AQ17 -> 0 | AD12: =Backend!AR17 | AE12: =Backend!AS17 -> 0.08348 | AF12: =Backend!AT17 -> 0.02609 | AG12: =Backend!AU17 | AH12: =Backend!AV17 -> 0 | AI12: =Backend!AW17 -> 0 | ... AV12: =Backend!BJ17 | AW12: =_xlfn.IFNA(Backend!O17,"") -> 3.31743 | AX12: =_xlfn.IFNA(IF(D12="","",Backend!BK17),"") -> 24.63136 | AY12: =IF(AX12="","",AX12*G12) -> 24.63136
A13: 11 | B13: =B12 -> FWR10000 | C13: 3 | D13: H 157 01 464 A Slider Upper Track | F13: Slider Upper Track | G13: 2 | H13: Sheet Metal-B | I13: Inhouse | J13: CSC | K13: =_xlfn.IFNA(Backend!AN18,"") -> 21.32976 | L13: =IFERROR(AA13,"") -> 24.32889 | M13: =IFERROR(AW13,"") -> 9.73113 | N13: =IF(SUM(AB13:AS13)=0,"",SUM(AB13:AS13)) -> 4.23591 | O13: =IF(SUM(AT13:AV13)=0,"",SUM(AT13:AV13)) -> 2.73952 | P13: =IF(K13="","",SUM(K13:O13)) -> 62.36521 | Q13: =IF(P13="","",P13*G13) -> 124.73042 | T13: =_xlfn.IFNA(IF(VLOOKUP(D13,Group!C:I,7,0)=0,"",VLOOKUP(D13,Group!C:I,7,0)),"") -> 0.385 | U13: =IFERROR(T13*G13,"") -> 0.77 | V13: =IFERROR(AY13/U13,"") -> 161.98756 | AA13: =_xlfn.IFNA(Backend!AO18,"") -> 24.32889 | AB13: =Backend!AP18 -> 0.47992 | AC13: =Backend!AQ18 -> 0 | AD13: =Backend!AR18 | AE13: =Backend!AS18 -> 0.10665 | AF13: =Backend!AT18 -> 0.24329 | AG13: =Backend!AU18 | AH13: =Backend!AV18 -> 0 | AI13: =Backend!AW18 -> 0 | ... AV13: =Backend!BJ18 | AW13: =_xlfn.IFNA(Backend!O18,"") -> 9.73113 | AX13: =_xlfn.IFNA(IF(D13="","",Backend!BK18),"") -> 62.36521 | AY13: =IF(AX13="","",AX13*G13) -> 124.73042
A14: 12 | B14: =B13 -> FWR10000 | C14: 3 | D14: H 157 01 464 A Slider Lower Track | F14: Slider Lower Track | G14: 2 | H14: Sheet Metal-B | I14: Inhouse | J14: CSC | K14: =_xlfn.IFNA(Backend!AN19,"") -> 24.41607 | L14: =IFERROR(AA14,"") -> 6.97526 | M14: =IFERROR(AW14,"") -> 11.39932 | N14: =IF(SUM(AB14:AS14)=0,"",SUM(AB14:AS14)) -> 1.71773 | O14: =IF(SUM(AT14:AV14)=0,"",SUM(AT14:AV14)) -> 1.88348 | P14: =IF(K14="","",SUM(K14:O14)) -> 46.39186 | Q14: =IF(P14="","",P14*G14) -> 92.78372 | T14: =_xlfn.IFNA(IF(VLOOKUP(D14,Group!C:I,7,0)=0,"",VLOOKUP(D14,Group!C:I,7,0)),"") -> 0.451 | U14: =IFERROR(T14*G14,"") -> 0.902 | V14: =IFERROR(AY14/U14,"") -> 102.86443 | AA14: =_xlfn.IFNA(Backend!AO19,"") -> 6.97526 | AB14: =Backend!AP19 -> 0.54936 | AC14: =Backend!AQ19 -> 0 | AD14: =Backend!AR19 | AE14: =Backend!AS19 -> 0.12208 | AF14: =Backend!AT19 -> 0.06975 | AG14: =Backend!AU19 | AH14: =Backend!AV19 -> 0 | AI14: =Backend!AW19 -> 0 | ... AV14: =Backend!BJ19 | AW14: =_xlfn.IFNA(Backend!O19,"") -> 11.39932 | AX14: =_xlfn.IFNA(IF(D14="","",Backend!BK19),"") -> 46.39186 | AY14: =IF(AX14="","",AX14*G14) -> 92.78372
A15: 13 | B15: =B14 -> FWR10000 | C15: 3 | D15: H 157 01 464 A Slider Upper Track plate | F15: Slider Upper Track plate | G15: 2 | H15: Sheet Metal-B | I15: Inhouse | J15: CSC | K15: =_xlfn.IFNA(Backend!AN20,"") -> 2.23646 | L15: =IFERROR(AA15,"") -> 23.27794 | M15: =IFERROR(AW15,"") -> 1.36489 | N15: =IF(SUM(AB15:AS15)=0,"",SUM(AB15:AS15)) -> 3.55319 | O15: =IF(SUM(AT15:AV15)=0,"",SUM(AT15:AV15)) -> 1.53087 | P15: =IF(K15="","",SUM(K15:O15)) -> 31.96335 | Q15: =IF(P15="","",P15*G15) -> 63.9267 | T15: =_xlfn.IFNA(IF(VLOOKUP(D15,Group!C:I,7,0)=0,"",VLOOKUP(D15,Group!C:I,7,0)),"") -> 0.036 | U15: =IFERROR(T15*G15,"") -> 0.072 | V15: =IFERROR(AY15/U15,"") -> 887.87083 | AA15: =_xlfn.IFNA(Backend!AO20,"") -> 23.27794 | AB15: =Backend!AP20 -> 0.05032 | AC15: =Backend!AQ20 -> 0 | AD15: =Backend!AR20 | AE15: =Backend!AS20 -> 0.01118 | AF15: =Backend!AT20 -> 0.23278 | AG15: =Backend!AU20 | AH15: =Backend!AV20 -> 0 | AI15: =Backend!AW20 -> 0 | ... AV15: =Backend!BJ20 | AW15: =_xlfn.IFNA(Backend!O20,"") -> 1.36489 | AX15: =_xlfn.IFNA(IF(D15="","",Backend!BK20),"") -> 31.96335 | AY15: =IF(AX15="","",AX15*G15) -> 63.9267
A16: 14 | B16: =B15 -> FWR10000 | C16: 3 | D16: H 157 01 464 A Slider Lower Track REINF | F16: Slider Lower Track REINF | G16: 2 | H16: Sheet Metal-B | I16: Inhouse | J16: CSC | K16: =_xlfn.IFNA(Backend!AN21,"") -> 3.15506 | L16: =IFERROR(AA16,"") -> 1.22199 | M16: =IFERROR(AW16,"") -> 1.31433 | N16: =IF(SUM(AB16:AS16)=0,"",SUM(AB16:AS16)) -> 0.27007 | O16: =IF(SUM(AT16:AV16)=0,"",SUM(AT16:AV16)) -> 0.26262 | P16: =IF(K16="","",SUM(K16:O16)) -> 6.22407 | Q16: =IF(P16="","",P16*G16) -> 12.44814 | T16: =_xlfn.IFNA(IF(VLOOKUP(D16,Group!C:I,7,0)=0,"",VLOOKUP(D16,Group!C:I,7,0)),"") -> 0.052 | U16: =IFERROR(T16*G16,"") -> 0.104 | V16: =IFERROR(AY16/U16,"") -> 119.69365 | AA16: =_xlfn.IFNA(Backend!AO21,"") -> 1.22199 | AB16: =Backend!AP21 -> 0.07099 | AC16: =Backend!AQ21 -> 0 | AD16: =Backend!AR21 | AE16: =Backend!AS21 -> 0.01578 | AF16: =Backend!AT21 -> 0.01222 | AG16: =Backend!AU21 | AH16: =Backend!AV21 -> 0 | AI16: =Backend!AW21 -> 0 | ... AV16: =Backend!BJ21 | AW16: =_xlfn.IFNA(Backend!O21,"") -> 1.31433 | AX16: =_xlfn.IFNA(IF(D16="","",Backend!BK21),"") -> 6.22407 | AY16: =IF(AX16="","",AX16*G16) -> 12.44814
... A24: 22 | B24: =B23 -> FWR10000 | C24: 3 | D24: H 157 01 464 A Slider Rivet Ø6mm | F24: Slider Rivet Ø6mm | G24: 4 | H24: Sheet Metal-B | I24: BOF | J24: Standard | K24: =_xlfn.IFNA(Backend!AN29,"") -> 1.8 | L24: =IFERROR(AA24,"") | M24: =IFERROR(AW24,"") | N24: =IF(SUM(AB24:AS24)=0,"",SUM(AB24:AS24)) -> 0.036 | O24: =IF(SUM(AT24:AV24)=0,"",SUM(AT24:AV24)) -> 0.054 | P24: =IF(K24="","",SUM(K24:O24)) -> 1.89 | Q24: =IF(P24="","",P24*G24) -> 7.56 | T24: =_xlfn.IFNA(IF(VLOOKUP(D24,Group!C:I,7,0)=0,"",VLOOKUP(D24,Group!C:I,7,0)),"") | U24: =IFERROR(T24*G24,"") | V24: =IFERROR(AY24/U24,"") | AA24: =_xlfn.IFNA(Backend!AO29,"") | AB24: =Backend!AP29 | AC24: =Backend!AQ29 | AD24: =Backend!AR29 -> 0.027 | AE24: =Backend!AS29 | AF24: =Backend!AT29 | AG24: =Backend!AU29 -> 0.009 | AH24: =Backend!AV29 | AI24: =Backend!AW29 | ... AV24: =Backend!BJ29 -> 0.054 | AW24: =_xlfn.IFNA(Backend!O29,"") | AX24: =_xlfn.IFNA(IF(D24="","",Backend!BK29),"") -> 1.89 | AY24: =IF(AX24="","",AX24*G24) -> 7.56
A25: 23 | B25: =B24 -> FWR10000 | C25: 2 | D25: H 157 01 465 S | E25: 2 | F25: TETHER BELT BOTTOM BRKT | G25: 1 | H25: Sheet Metal-B | I25: Inhouse | J25: CSC | K25: =_xlfn.IFNA(Backend!AN30,"") -> 26.23889 | L25: =IFERROR(AA25,"") -> 4.38942 | M25: =IFERROR(AW25,"") -> 4.8121 | N25: =IF(SUM(AB25:AS25)=0,"",SUM(AB25:AS25)) -> 1.37997 | O25: =IF(SUM(AT25:AV25)=0,"",SUM(AT25:AV25)) -> 1.8377 | P25: =IF(K25="","",SUM(K25:O25)) -> 38.65808 | Q25: =IF(P25="","",P25*G25) -> 38.65808 | T25: =_xlfn.IFNA(IF(VLOOKUP(D25,Group!C:I,7,0)=0,"",VLOOKUP(D25,Group!C:I,7,0)),"") -> 0.33 | U25: =IFERROR(T25*G25,"") -> 0.33 | V25: =IFERROR(AY25/U25,"") -> 117.1457 | AA25: =_xlfn.IFNA(Backend!AO30,"") -> 4.38942 | AB25: =Backend!AP30 -> 0.59037 | AC25: =Backend!AQ30 -> 0 | AD25: =Backend!AR30 | AE25: =Backend!AS30 -> 0.13119 | AF25: =Backend!AT30 -> 0.04389 | AG25: =Backend!AU30 | AH25: =Backend!AV30 -> 0 | AI25: =Backend!AW30 -> 0 | ... AV25: =Backend!BJ30 | AW25: =_xlfn.IFNA(Backend!O30,"") -> 4.8121 | AX25: =_xlfn.IFNA(IF(D25="","",Backend!BK30),"") -> 38.65808 | AY25: =IF(AX25="","",AX25*G25) -> 38.65808
A26: 24 | B26: =B25 -> FWR10000 | C26: 2 | D26: H 157 01 270 A | E26: 3 | F26: Pnematic suspension CV | G26: 1 | H26: Assembly | I26: Inhouse | J26: CSC | K26: =_xlfn.IFNA(Backend!AN31,"") -> 0 | L26: =IFERROR(AA26,"") -> 0 | M26: =IFERROR(AW26,"") -> 0 | N26: =IF(SUM(AB26:AS26)=0,"",SUM(AB26:AS26)) | O26: =IF(SUM(AT26:AV26)=0,"",SUM(AT26:AV26)) | P26: =IF(K26="","",SUM(K26:O26)) -> 0 | Q26: =IF(P26="","",P26*G26) -> 0 | T26: =_xlfn.IFNA(IF(VLOOKUP(D26,Group!C:I,7,0)=0,"",VLOOKUP(D26,Group!C:I,7,0)),"") | U26: =IFERROR(T26*G26,"") | V26: =IFERROR(AY26/U26,"") | AA26: =_xlfn.IFNA(Backend!AO31,"") -> 0 | AB26: =Backend!AP31 -> 0 | AC26: =Backend!AQ31 -> 0 | AD26: =Backend!AR31 | AE26: =Backend!AS31 -> 0 | AF26: =Backend!AT31 -> 0 | AG26: =Backend!AU31 | AH26: =Backend!AV31 -> 0 | AI26: =Backend!AW31 -> 0 | ... AV26: =Backend!BJ31 | AW26: =_xlfn.IFNA(Backend!O31,"") -> 0 | AX26: =_xlfn.IFNA(IF(D26="","",Backend!BK31),"") -> 0 | AY26: =IF(AX26="","",AX26*G26) -> 0
A27: 25 | B27: =B26 -> FWR10000 | C27: 3 | D27: H 157 01 270 A Botttom Frame | F27: Botttom Frame | G27: 1 | H27: Sheet Metal-B | I27: Inhouse | J27: LPP-Thumbrule | K27: =_xlfn.IFNA(Backend!AN32,"") -> 641.7 | L27: =IFERROR(AA27,"") | M27: =IFERROR(AW27,"") | N27: =IF(SUM(AB27:AS27)=0,"",SUM(AB27:AS27)) | O27: =IF(SUM(AT27:AV27)=0,"",SUM(AT27:AV27)) | P27: =IF(K27="","",SUM(K27:O27)) -> 641.7 | Q27: =IF(P27="","",P27*G27) -> 641.7 | T27: =_xlfn.IFNA(IF(VLOOKUP(D27,Group!C:I,7,0)=0,"",VLOOKUP(D27,Group!C:I,7,0)),"") -> 4.278 | U27: =IFERROR(T27*G27,"") -> 4.278 | V27: =IFERROR(AY27/U27,"") -> 150 | AA27: =_xlfn.IFNA(Backend!AO32,"") | AB27: =Backend!AP32 | AC27: =Backend!AQ32 | AD27: =Backend!AR32 | AE27: =Backend!AS32 | AF27: =Backend!AT32 | AG27: =Backend!AU32 | AH27: =Backend!AV32 | AI27: =Backend!AW32 | ... AV27: =Backend!BJ32 | AW27: =_xlfn.IFNA(Backend!O32,"") | AX27: =_xlfn.IFNA(IF(D27="","",Backend!BK32),"") -> 641.7 | AY27: =IF(AX27="","",AX27*G27) -> 641.7
A28: 26 | B28: =B27 -> FWR10000 | C28: 3 | D28: H 157 01 270 A Outer Roller set | F28: Outer Roller set | G28: 1 | H28: Sheet Metal-B | I28: Inhouse | J28: LPP-Thumbrule | K28: =_xlfn.IFNA(Backend!AN33,"") -> 357.6 | L28: =IFERROR(AA28,"") | M28: =IFERROR(AW28,"") | N28: =IF(SUM(AB28:AS28)=0,"",SUM(AB28:AS28)) | O28: =IF(SUM(AT28:AV28)=0,"",SUM(AT28:AV28)) | P28: =IF(K28="","",SUM(K28:O28)) -> 357.6 | Q28: =IF(P28="","",P28*G28) -> 357.6 | T28: =_xlfn.IFNA(IF(VLOOKUP(D28,Group!C:I,7,0)=0,"",VLOOKUP(D28,Group!C:I,7,0)),"") -> 2.384 | U28: =IFERROR(T28*G28,"") -> 2.384 | V28: =IFERROR(AY28/U28,"") -> 150 | AA28: =_xlfn.IFNA(Backend!AO33,"") | AB28: =Backend!AP33 | AC28: =Backend!AQ33 | AD28: =Backend!AR33 | AE28: =Backend!AS33 | AF28: =Backend!AT33 | AG28: =Backend!AU33 | AH28: =Backend!AV33 | AI28: =Backend!AW33 | ... AV28: =Backend!BJ33 | AW28: =_xlfn.IFNA(Backend!O33,"") | AX28: =_xlfn.IFNA(IF(D28="","",Backend!BK33),"") -> 357.6 | AY28: =IF(AX28="","",AX28*G28) -> 357.6
A29: 27 | B29: =B28 -> FWR10000 | C29: 3 | D29: H 157 01 270 A Inner Roller set | F29: Inner Roller set | G29: 1 | H29: Sheet Metal-B | I29: Inhouse | J29: LPP-Thumbrule | K29: =_xlfn.IFNA(Backend!AN34,"") -> 428.55 | L29: =IFERROR(AA29,"") | M29: =IFERROR(AW29,"") | N29: =IF(SUM(AB29:AS29)=0,"",SUM(AB29:AS29)) | O29: =IF(SUM(AT29:AV29)=0,"",SUM(AT29:AV29)) | P29: =IF(K29="","",SUM(K29:O29)) -> 428.55 | Q29: =IF(P29="","",P29*G29) -> 428.55 | T29: =_xlfn.IFNA(IF(VLOOKUP(D29,Group!C:I,7,0)=0,"",VLOOKUP(D29,Group!C:I,7,0)),"") -> 2.857 | U29: =IFERROR(T29*G29,"") -> 2.857 | V29: =IFERROR(AY29/U29,"") -> 150 | AA29: =_xlfn.IFNA(Backend!AO34,"") | AB29: =Backend!AP34 | AC29: =Backend!AQ34 | AD29: =Backend!AR34 | AE29: =Backend!AS34 | AF29: =Backend!AT34 | AG29: =Backend!AU34 | AH29: =Backend!AV34 | AI29: =Backend!AW34 | ... AV29: =Backend!BJ34 | AW29: =_xlfn.IFNA(Backend!O34,"") | AX29: =_xlfn.IFNA(IF(D29="","",Backend!BK34),"") -> 428.55 | AY29: =IF(AX29="","",AX29*G29) -> 428.55
A30: 28 | B30: =B29 -> FWR10000 | C30: 3 | D30: H 157 01 270 A Outer Roller Bearing case | F30: Outer Roller Bearing case | G30: 2 | H30: Injection Moulding | I30: BOF | J30: CSC | K30: =_xlfn.IFNA(Backend!AN35,"") -> 13.29261 | L30: =IFERROR(AA30,"") | M30: =IFERROR(AW30,"") | N30: =IF(SUM(AB30:AS30)=0,"",SUM(AB30:AS30)) -> 0.69786 | O30: =IF(SUM(AT30:AV30)=0,"",SUM(AT30:AV30)) -> 1.19633 | P30: =IF(K30="","",SUM(K30:O30)) -> 15.1868 | Q30: =IF(P30="","",P30*G30) -> 30.3736 | T30: =_xlfn.IFNA(IF(VLOOKUP(D30,Group!C:I,7,0)=0,"",VLOOKUP(D30,Group!C:I,7,0)),"") -> 0.02 | U30: =IFERROR(T30*G30,"") -> 0.04 | V30: =IFERROR(AY30/U30,"") -> 759.34 | AA30: =_xlfn.IFNA(Backend!AO35,"") | AB30: =Backend!AP35 | AC30: =Backend!AQ35 | AD30: =Backend!AR35 -> 0.29908 | AE30: =Backend!AS35 | AF30: =Backend!AT35 | AG30: =Backend!AU35 -> 0.39878 | AH30: =Backend!AV35 | AI30: =Backend!AW35 | ... AV30: =Backend!BJ35 -> 1.19633 | AW30: =_xlfn.IFNA(Backend!O35,"") | AX30: =_xlfn.IFNA(IF(D30="","",Backend!BK35),"") -> 15.1868 | AY30: =IF(AX30="","",AX30*G30) -> 30.3736
A31: 29 | B31: =B30 -> FWR10000 | C31: 3 | D31: H 157 01 270 A Outer Roller Wheel | F31: Outer Roller Wheel | G31: 2 | H31: Injection Moulding | I31: BOF | J31: CSC | K31: =_xlfn.IFNA(Backend!AN36,"") -> 8.62449 | L31: =IFERROR(AA31,"") | M31: =IFERROR(AW31,"") | N31: =IF(SUM(AB31:AS31)=0,"",SUM(AB31:AS31)) -> 0.45278 | O31: =IF(SUM(AT31:AV31)=0,"",SUM(AT31:AV31)) -> 0.7762 | P31: =IF(K31="","",SUM(K31:O31)) -> 9.85347 | Q31: =IF(P31="","",P31*G31) -> 19.70694 | T31: =_xlfn.IFNA(IF(VLOOKUP(D31,Group!C:I,7,0)=0,"",VLOOKUP(D31,Group!C:I,7,0)),"") -> 0.012 | U31: =IFERROR(T31*G31,"") -> 0.024 | V31: =IFERROR(AY31/U31,"") -> 821.1225 | AA31: =_xlfn.IFNA(Backend!AO36,"") | AB31: =Backend!AP36 | AC31: =Backend!AQ36 | AD31: =Backend!AR36 -> 0.19405 | AE31: =Backend!AS36 | AF31: =Backend!AT36 | AG31: =Backend!AU36 -> 0.25873 | AH31: =Backend!AV36 | AI31: =Backend!AW36 | ... AV31: =Backend!BJ36 -> 0.7762 | AW31: =_xlfn.IFNA(Backend!O36,"") | AX31: =_xlfn.IFNA(IF(D31="","",Backend!BK36),"") -> 9.85347 | AY31: =IF(AX31="","",AX31*G31) -> 19.70694
A32: 30 | B32: =B31 -> FWR10000 | C32: 3 | D32: H 157 01 270 A Inner Roller Bearing case | F32: Inner Roller Bearing case | G32: 2 | H32: Injection Moulding | I32: BOF | J32: CSC | K32: =_xlfn.IFNA(Backend!AN37,"") -> 31.69207 | L32: =IFERROR(AA32,"") | M32: =IFERROR(AW32,"") | N32: =IF(SUM(AB32:AS32)=0,"",SUM(AB32:AS32)) -> 1.66383 | O32: =IF(SUM(AT32:AV32)=0,"",SUM(AT32:AV32)) -> 2.85229 | P32: =IF(K32="","",SUM(K32:O32)) -> 36.20819 | Q32: =IF(P32="","",P32*G32) -> 72.41638 | T32: =_xlfn.IFNA(IF(VLOOKUP(D32,Group!C:I,7,0)=0,"",VLOOKUP(D32,Group!C:I,7,0)),"") -> 0.052 | U32: =IFERROR(T32*G32,"") -> 0.104 | V32: =IFERROR(AY32/U32,"") -> 696.31135 | AA32: =_xlfn.IFNA(Backend!AO37,"") | AB32: =Backend!AP37 | AC32: =Backend!AQ37 | AD32: =Backend!AR37 -> 0.71307 | AE32: =Backend!AS37 | AF32: =Backend!AT37 | AG32: =Backend!AU37 -> 0.95076 | AH32: =Backend!AV37 | AI32: =Backend!AW37 | ... AV32: =Backend!BJ37 -> 2.85229 | AW32: =_xlfn.IFNA(Backend!O37,"") | AX32: =_xlfn.IFNA(IF(D32="","",Backend!BK37),"") -> 36.20819 | AY32: =IF(AX32="","",AX32*G32) -> 72.41638
A33: 31 | B33: =B32 -> FWR10000 | C33: 3 | D33: H 157 01 270 A Inner Roller Wheel | F33: Inner Roller Wheel | G33: 2 | H33: Injection Moulding | I33: BOF | J33: CSC | K33: =_xlfn.IFNA(Backend!AN38,"") -> 8.62449 | L33: =IFERROR(AA33,"") | M33: =IFERROR(AW33,"") | N33: =IF(SUM(AB33:AS33)=0,"",SUM(AB33:AS33)) -> 0.45278 | O33: =IF(SUM(AT33:AV33)=0,"",SUM(AT33:AV33)) -> 0.7762 | P33: =IF(K33="","",SUM(K33:O33)) -> 9.85347 | Q33: =IF(P33="","",P33*G33) -> 19.70694 | T33: =_xlfn.IFNA(IF(VLOOKUP(D33,Group!C:I,7,0)=0,"",VLOOKUP(D33,Group!C:I,7,0)),"") -> 0.012 | U33: =IFERROR(T33*G33,"") -> 0.024 | V33: =IFERROR(AY33/U33,"") -> 821.1225 | AA33: =_xlfn.IFNA(Backend!AO38,"") | AB33: =Backend!AP38 | AC33: =Backend!AQ38 | AD33: =Backend!AR38 -> 0.19405 | AE33: =Backend!AS38 | AF33: =Backend!AT38 | AG33: =Backend!AU38 -> 0.25873 | AH33: =Backend!AV38 | AI33: =Backend!AW38 | ... AV33: =Backend!BJ38 -> 0.7762 | AW33: =_xlfn.IFNA(Backend!O38,"") | AX33: =_xlfn.IFNA(IF(D33="","",Backend!BK38),"") -> 9.85347 | AY33: =IF(AX33="","",AX33*G33) -> 19.70694
A34: 32 | B34: =B33 -> FWR10000 | C34: 3 | D34: H 157 01 270 A Rail Brkt Front | F34: Rail Brkt Front | G34: 1 | H34: Sheet Metal-B | I34: Inhouse | J34: LPP-Thumbrule | K34: =_xlfn.IFNA(Backend!AN39,"") -> 361.95 | L34: =IFERROR(AA34,"") | M34: =IFERROR(AW34,"") | N34: =IF(SUM(AB34:AS34)=0,"",SUM(AB34:AS34)) | O34: =IF(SUM(AT34:AV34)=0,"",SUM(AT34:AV34)) | P34: =IF(K34="","",SUM(K34:O34)) -> 361.95 | Q34: =IF(P34="","",P34*G34) -> 361.95 | T34: =_xlfn.IFNA(IF(VLOOKUP(D34,Group!C:I,7,0)=0,"",VLOOKUP(D34,Group!C:I,7,0)),"") -> 2.413 | U34: =IFERROR(T34*G34,"") -> 2.413 | V34: =IFERROR(AY34/U34,"") -> 150 | AA34: =_xlfn.IFNA(Backend!AO39,"") | AB34: =Backend!AP39 | AC34: =Backend!AQ39 | AD34: =Backend!AR39 | AE34: =Backend!AS39 | AF34: =Backend!AT39 | AG34: =Backend!AU39 | AH34: =Backend!AV39 | AI34: =Backend!AW39 | ... AV34: =Backend!BJ39 | AW34: =_xlfn.IFNA(Backend!O39,"") | AX34: =_xlfn.IFNA(IF(D34="","",Backend!BK39),"") -> 361.95 | AY34: =IF(AX34="","",AX34*G34) -> 361.95
A35: 33 | B35: =B34 -> FWR10000 | C35: 3 | D35: H 157 01 270 A Rail Brkt Rear | F35: Rail Brkt Rear | G35: 1 | H35: Sheet Metal-B | I35: Inhouse | J35: LPP-Thumbrule | K35: =_xlfn.IFNA(Backend!AN40,"") -> 154.2 | L35: =IFERROR(AA35,"") | M35: =IFERROR(AW35,"") | N35: =IF(SUM(AB35:AS35)=0,"",SUM(AB35:AS35)) | O35: =IF(SUM(AT35:AV35)=0,"",SUM(AT35:AV35)) | P35: =IF(K35="","",SUM(K35:O35)) -> 154.2 | Q35: =IF(P35="","",P35*G35) -> 154.2 | T35: =_xlfn.IFNA(IF(VLOOKUP(D35,Group!C:I,7,0)=0,"",VLOOKUP(D35,Group!C:I,7,0)),"") -> 1.028 | U35: =IFERROR(T35*G35,"") -> 1.028 | V35: =IFERROR(AY35/U35,"") -> 150 | AA35: =_xlfn.IFNA(Backend!AO40,"") | AB35: =Backend!AP40 | AC35: =Backend!AQ40 | AD35: =Backend!AR40 | AE35: =Backend!AS40 | AF35: =Backend!AT40 | AG35: =Backend!AU40 | AH35: =Backend!AV40 | AI35: =Backend!AW40 | ... AV35: =Backend!BJ40 | AW35: =_xlfn.IFNA(Backend!O40,"") | AX35: =_xlfn.IFNA(IF(D35="","",Backend!BK40),"") -> 154.2 | AY35: =IF(AX35="","",AX35*G35) -> 154.2
A36: 34 | B36: =B35 -> FWR10000 | C36: 3 | D36: H 157 01 270 A Bellow | F36: Bellow | G36: 1 | H36: Compression Moulding | I36: BOF | J36: CSC | K36: =_xlfn.IFNA(Backend!AN41,"") -> 519.25848 | L36: =IFERROR(AA36,"") | M36: =IFERROR(AW36,"") | N36: =IF(SUM(AB36:AS36)=0,"",SUM(AB36:AS36)) | O36: =IF(SUM(AT36:AV36)=0,"",SUM(AT36:AV36)) | P36: =IF(K36="","",SUM(K36:O36)) -> 519.25848 | Q36: =IF(P36="","",P36*G36) -> 519.25848 | T36: =_xlfn.IFNA(IF(VLOOKUP(D36,Group!C:I,7,0)=0,"",VLOOKUP(D36,Group!C:I,7,0)),"") -> 1.536 | U36: =IFERROR(T36*G36,"") -> 1.536 | V36: =IFERROR(AY36/U36,"") -> 338.05891 | AA36: =_xlfn.IFNA(Backend!AO41,"") | AB36: =Backend!AP41 | AC36: =Backend!AQ41 | AD36: =Backend!AR41 -> 0 | AE36: =Backend!AS41 | AF36: =Backend!AT41 | AG36: =Backend!AU41 -> 0 | AH36: =Backend!AV41 | AI36: =Backend!AW41 | ... AV36: =Backend!BJ41 -> 0 | AW36: =_xlfn.IFNA(Backend!O41,"") | AX36: =_xlfn.IFNA(IF(D36="","",Backend!BK41),"") -> 519.25848 | AY36: =IF(AX36="","",AX36*G36) -> 519.25848
A37: 35 | B37: =B36 -> FWR10000 | C37: 3 | D37: H 157 01 270 A M8*20 Screw Hex socket head | F37: M8*20 Screw Hex socket head | G37: 4 | H37: Sheet Metal-B | I37: BOF | J37: Reference | K37: =_xlfn.IFNA(Backend!AN42,"") -> 3.42 | L37: =IFERROR(AA37,"") | M37: =IFERROR(AW37,"") | N37: =IF(SUM(AB37:AS37)=0,"",SUM(AB37:AS37)) -> 0.0684 | O37: =IF(SUM(AT37:AV37)=0,"",SUM(AT37:AV37)) -> 0.1026 | P37: =IF(K37="","",SUM(K37:O37)) -> 3.591 | Q37: =IF(P37="","",P37*G37) -> 14.364 | T37: =_xlfn.IFNA(IF(VLOOKUP(D37,Group!C:I,7,0)=0,"",VLOOKUP(D37,Group!C:I,7,0)),"") | U37: =IFERROR(T37*G37,"") | V37: =IFERROR(AY37/U37,"") | AA37: =_xlfn.IFNA(Backend!AO42,"") | AB37: =Backend!AP42 | AC37: =Backend!AQ42 | AD37: =Backend!AR42 -> 0.0513 | AE37: =Backend!AS42 | AF37: =Backend!AT42 | AG37: =Backend!AU42 -> 0.0171 | AH37: =Backend!AV42 | AI37: =Backend!AW42 | ... AV37: =Backend!BJ42 -> 0.1026 | AW37: =_xlfn.IFNA(Backend!O42,"") | AX37: =_xlfn.IFNA(IF(D37="","",Backend!BK42),"") -> 3.591 | AY37: =IF(AX37="","",AX37*G37) -> 14.364
A38: 36 | B38: =B37 -> FWR10000 | C38: 3 | D38: H 157 01 270 A Bellow MtG Srip | F38: Bellow MtG Srip | G38: 1 | H38: Sheet Metal-B | I38: Inhouse | J38: LPP-Thumbrule | K38: =_xlfn.IFNA(Backend!AN43,"") -> 4.5 | L38: =IFERROR(AA38,"") | M38: =IFERROR(AW38,"") | N38: =IF(SUM(AB38:AS38)=0,"",SUM(AB38:AS38)) | O38: =IF(SUM(AT38:AV38)=0,"",SUM(AT38:AV38)) | P38: =IF(K38="","",SUM(K38:O38)) -> 4.5 | Q38: =IF(P38="","",P38*G38) -> 4.5 | T38: =_xlfn.IFNA(IF(VLOOKUP(D38,Group!C:I,7,0)=0,"",VLOOKUP(D38,Group!C:I,7,0)),"") -> 0.03 | U38: =IFERROR(T38*G38,"") -> 0.03 | V38: =IFERROR(AY38/U38,"") -> 150 | AA38: =_xlfn.IFNA(Backend!AO43,"") | AB38: =Backend!AP43 | AC38: =Backend!AQ43 | AD38: =Backend!AR43 | AE38: =Backend!AS43 | AF38: =Backend!AT43 | AG38: =Backend!AU43 | AH38: =Backend!AV43 | AI38: =Backend!AW43 | ... AV38: =Backend!BJ43 | AW38: =_xlfn.IFNA(Backend!O43,"") | AX38: =_xlfn.IFNA(IF(D38="","",Backend!BK43),"") -> 4.5 | AY38: =IF(AX38="","",AX38*G38) -> 4.5
A39: 37 | B39: =B38 -> FWR10000 | C39: 2 | D39: L 122 19 009 Q | E39: 7 | F39: Switch - Pneumatic height adj | G39: 1 | K39: =_xlfn.IFNA(Backend!AN44,"") | L39: =IFERROR(AA39,"") | M39: =IFERROR(AW39,"") | N39: =IF(SUM(AB39:AS39)=0,"",SUM(AB39:AS39)) | O39: =IF(SUM(AT39:AV39)=0,"",SUM(AT39:AV39)) | P39: =IF(K39="","",SUM(K39:O39)) | Q39: =IF(P39="","",P39*G39) | T39: =_xlfn.IFNA(IF(VLOOKUP(D39,Group!C:I,7,0)=0,"",VLOOKUP(D39,Group!C:I,7,0)),"") | U39: =IFERROR(T39*G39,"") | V39: =IFERROR(AY39/U39,"") | AA39: =_xlfn.IFNA(Backend!AO44,"") | AB39: =Backend!AP44 | AC39: =Backend!AQ44 | AD39: =Backend!AR44 | AE39: =Backend!AS44 | AF39: =Backend!AT44 | AG39: =Backend!AU44 | AH39: =Backend!AV44 | AI39: =Backend!AW44 | ... AV39: =Backend!BJ44 | AW39: =_xlfn.IFNA(Backend!O44,"") | AX39: =_xlfn.IFNA(IF(D39="","",Backend!BK44),"") -> 0 | AY39: =IF(AX39="","",AX39*G39) -> 0
A40: 38 | B40: =B39 -> FWR10000 | C40: 2 | D40: H 157 01 466 P | E40: 4 | F40: Side valance cover RH | G40: 1 | H40: Injection Moulding | I40: BOF | J40: CSC | K40: =_xlfn.IFNA(Backend!AN45,"") -> 49.9855 | L40: =IFERROR(AA40,"") | M40: =IFERROR(AW40,"") | N40: =IF(SUM(AB40:AS40)=0,"",SUM(AB40:AS40)) -> 2.62423 | O40: =IF(SUM(AT40:AV40)=0,"",SUM(AT40:AV40)) -> 4.49869 | P40: =IF(K40="","",SUM(K40:O40)) -> 57.10842 | Q40: =IF(P40="","",P40*G40) -> 57.10842 | T40: =_xlfn.IFNA(IF(VLOOKUP(D40,Group!C:I,7,0)=0,"",VLOOKUP(D40,Group!C:I,7,0)),"") -> 0.3 | U40: =IFERROR(T40*G40,"") -> 0.3 | V40: =IFERROR(AY40/U40,"") -> 190.3614 | AA40: =_xlfn.IFNA(Backend!AO45,"") | AB40: =Backend!AP45 | AC40: =Backend!AQ45 | AD40: =Backend!AR45 -> 1.12467 | AE40: =Backend!AS45 | AF40: =Backend!AT45 | AG40: =Backend!AU45 -> 1.49956 | AH40: =Backend!AV45 | AI40: =Backend!AW45 | ... AV40: =Backend!BJ45 -> 4.49869 | AW40: =_xlfn.IFNA(Backend!O45,"") | AX40: =_xlfn.IFNA(IF(D40="","",Backend!BK45),"") -> 57.10842 | AY40: =IF(AX40="","",AX40*G40) -> 57.10842
A41: 39 | B41: =B40 -> FWR10000 | C41: 2 | D41: H 157 01 467 P | E41: 5 | F41: Side valance cover LH | G41: 1 | H41: Injection Moulding | I41: BOF | J41: CSC | K41: =_xlfn.IFNA(Backend!AN46,"") -> 49.9855 | L41: =IFERROR(AA41,"") | M41: =IFERROR(AW41,"") | N41: =IF(SUM(AB41:AS41)=0,"",SUM(AB41:AS41)) -> 2.62423 | O41: =IF(SUM(AT41:AV41)=0,"",SUM(AT41:AV41)) -> 4.49869 | P41: =IF(K41="","",SUM(K41:O41)) -> 57.10842 | Q41: =IF(P41="","",P41*G41) -> 57.10842 | T41: =_xlfn.IFNA(IF(VLOOKUP(D41,Group!C:I,7,0)=0,"",VLOOKUP(D41,Group!C:I,7,0)),"") -> 0.3 | U41: =IFERROR(T41*G41,"") -> 0.3 | V41: =IFERROR(AY41/U41,"") -> 190.3614 | AA41: =_xlfn.IFNA(Backend!AO46,"") | AB41: =Backend!AP46 | AC41: =Backend!AQ46 | AD41: =Backend!AR46 -> 1.12467 | AE41: =Backend!AS46 | AF41: =Backend!AT46 | AG41: =Backend!AU46 -> 1.49956 | AH41: =Backend!AV46 | AI41: =Backend!AW46 | ... AV41: =Backend!BJ46 -> 4.49869 | AW41: =_xlfn.IFNA(Backend!O46,"") | AX41: =_xlfn.IFNA(IF(D41="","",Backend!BK46),"") -> 57.10842 | AY41: =IF(AX41="","",AX41*G41) -> 57.10842
A42: 40 | B42: =B41 -> FWR10000 | C42: 2 | D42: H 157 01 142 P | E42: 6 | F42: Front cover | G42: 1 | H42: Injection Moulding | I42: BOF | J42: CSC | K42: =_xlfn.IFNA(Backend!AN47,"") -> 13.10595 | L42: =IFERROR(AA42,"") | M42: =IFERROR(AW42,"") | N42: =IF(SUM(AB42:AS42)=0,"",SUM(AB42:AS42)) -> 0.68806 | O42: =IF(SUM(AT42:AV42)=0,"",SUM(AT42:AV42)) -> 1.17954 | P42: =IF(K42="","",SUM(K42:O42)) -> 14.97355 | Q42: =IF(P42="","",P42*G42) -> 14.97355 | T42: =_xlfn.IFNA(IF(VLOOKUP(D42,Group!C:I,7,0)=0,"",VLOOKUP(D42,Group!C:I,7,0)),"") -> 0.072 | U42: =IFERROR(T42*G42,"") -> 0.072 | V42: =IFERROR(AY42/U42,"") -> 207.96597 | AA42: =_xlfn.IFNA(Backend!AO47,"") | AB42: =Backend!AP47 | AC42: =Backend!AQ47 | AD42: =Backend!AR47 -> 0.29488 | AE42: =Backend!AS47 | AF42: =Backend!AT47 | AG42: =Backend!AU47 -> 0.39318 | AH42: =Backend!AV47 | AI42: =Backend!AW47 | ... AV42: =Backend!BJ47 -> 1.17954 | AW42: =_xlfn.IFNA(Backend!O47,"") | AX42: =_xlfn.IFNA(IF(D42="","",Backend!BK47),"") -> 14.97355 | AY42: =IF(AX42="","",AX42*G42) -> 14.97355
A43: 41 | B43: =B42 -> FWR10000 | C43: 2 | D43: H 157 01 468 P | E43: 8 | F43: Recliner handle | G43: 1 | H43: Injection Moulding | I43: BOF | J43: CSC | K43: =_xlfn.IFNA(Backend!AN48,"") -> 12.1023 | L43: =IFERROR(AA43,"") | M43: =IFERROR(AW43,"") | N43: =IF(SUM(AB43:AS43)=0,"",SUM(AB43:AS43)) -> 0.63537 | O43: =IF(SUM(AT43:AV43)=0,"",SUM(AT43:AV43)) -> 1.08921 | P43: =IF(K43="","",SUM(K43:O43)) -> 13.82688 | Q43: =IF(P43="","",P43*G43) -> 13.82688 | T43: =_xlfn.IFNA(IF(VLOOKUP(D43,Group!C:I,7,0)=0,"",VLOOKUP(D43,Group!C:I,7,0)),"") -> 0.038 | U43: =IFERROR(T43*G43,"") -> 0.038 | V43: =IFERROR(AY43/U43,"") -> 363.86526 | AA43: =_xlfn.IFNA(Backend!AO48,"") | AB43: =Backend!AP48 | AC43: =Backend!AQ48 | AD43: =Backend!AR48 -> 0.2723 | AE43: =Backend!AS48 | AF43: =Backend!AT48 | AG43: =Backend!AU48 -> 0.36307 | AH43: =Backend!AV48 | AI43: =Backend!AW48 | ... AV43: =Backend!BJ48 -> 1.08921 | AW43: =_xlfn.IFNA(Backend!O48,"") | AX43: =_xlfn.IFNA(IF(D43="","",Backend!BK48),"") -> 13.82688 | AY43: =IF(AX43="","",AX43*G43) -> 13.82688
A44: 42 | B44: =B43 -> FWR10000 | C44: 2 | D44: H 157 01 014 D | E44: 9 | F44: ASSY Backrest complete | G44: 1 | H44: Sheet Metal-B | I44: Inhouse | J44: LPP-Thumbrule | K44: =_xlfn.IFNA(Backend!AN49,"") -> 1030.05 | L44: =IFERROR(AA44,"") | M44: =IFERROR(AW44,"") | N44: =IF(SUM(AB44:AS44)=0,"",SUM(AB44:AS44)) | O44: =IF(SUM(AT44:AV44)=0,"",SUM(AT44:AV44)) | P44: =IF(K44="","",SUM(K44:O44)) -> 1030.05 | Q44: =IF(P44="","",P44*G44) -> 1030.05 | T44: =_xlfn.IFNA(IF(VLOOKUP(D44,Group!C:I,7,0)=0,"",VLOOKUP(D44,Group!C:I,7,0)),"") -> 6.867 | U44: =IFERROR(T44*G44,"") -> 6.867 | V44: =IFERROR(AY44/U44,"") -> 150 | AA44: =_xlfn.IFNA(Backend!AO49,"") | AB44: =Backend!AP49 | AC44: =Backend!AQ49 | AD44: =Backend!AR49 | AE44: =Backend!AS49 | AF44: =Backend!AT49 | AG44: =Backend!AU49 | AH44: =Backend!AV49 | AI44: =Backend!AW49 | ... AV44: =Backend!BJ49 | AW44: =_xlfn.IFNA(Backend!O49,"") | AX44: =_xlfn.IFNA(IF(D44="","",Backend!BK49),"") -> 1030.05 | AY44: =IF(AX44="","",AX44*G44) -> 1030.05
A45: 43 | B45: =B44 -> FWR10000 | C45: 2 | D45: H 157 01 473 D | E45: 10 | F45: ASSY seat base frame | G45: 1 | H45: Sheet Metal-B | I45: Inhouse | J45: LPP-Thumbrule | K45: =_xlfn.IFNA(Backend!AN50,"") -> 603.45 | L45: =IFERROR(AA45,"") | M45: =IFERROR(AW45,"") | N45: =IF(SUM(AB45:AS45)=0,"",SUM(AB45:AS45)) | O45: =IF(SUM(AT45:AV45)=0,"",SUM(AT45:AV45)) | P45: =IF(K45="","",SUM(K45:O45)) -> 603.45 | Q45: =IF(P45="","",P45*G45) -> 603.45 | T45: =_xlfn.IFNA(IF(VLOOKUP(D45,Group!C:I,7,0)=0,"",VLOOKUP(D45,Group!C:I,7,0)),"") -> 4.023 | U45: =IFERROR(T45*G45,"") -> 4.023 | V45: =IFERROR(AY45/U45,"") -> 150 | AA45: =_xlfn.IFNA(Backend!AO50,"") | AB45: =Backend!AP50 | AC45: =Backend!AQ50 | AD45: =Backend!AR50 | AE45: =Backend!AS50 | AF45: =Backend!AT50 | AG45: =Backend!AU50 | AH45: =Backend!AV50 | AI45: =Backend!AW50 | ... AV45: =Backend!BJ50 | AW45: =_xlfn.IFNA(Backend!O50,"") | AX45: =_xlfn.IFNA(IF(D45="","",Backend!BK50),"") -> 603.45 | AY45: =IF(AX45="","",AX45*G45) -> 603.45
A46: 44 | B46: =B45 -> FWR10000 | C46: 2 | D46: H 157 01 414 W | E46: 11 | F46: Sprial Spring 30deg | G46: 2 | H46: Sheet Metal-B | I46: Inhouse | J46: LPP-Thumbrule | K46: =_xlfn.IFNA(Backend!AN51,"") -> 10.35 | L46: =IFERROR(AA46,"") | M46: =IFERROR(AW46,"") | N46: =IF(SUM(AB46:AS46)=0,"",SUM(AB46:AS46)) | O46: =IF(SUM(AT46:AV46)=0,"",SUM(AT46:AV46)) | P46: =IF(K46="","",SUM(K46:O46)) -> 10.35 | Q46: =IF(P46="","",P46*G46) -> 20.7 | T46: =_xlfn.IFNA(IF(VLOOKUP(D46,Group!C:I,7,0)=0,"",VLOOKUP(D46,Group!C:I,7,0)),"") -> 0.069 | U46: =IFERROR(T46*G46,"") -> 0.138 | V46: =IFERROR(AY46/U46,"") -> 150 | AA46: =_xlfn.IFNA(Backend!AO51,"") | AB46: =Backend!AP51 | AC46: =Backend!AQ51 | AD46: =Backend!AR51 | AE46: =Backend!AS51 | AF46: =Backend!AT51 | AG46: =Backend!AU51 | AH46: =Backend!AV51 | AI46: =Backend!AW51 | ... AV46: =Backend!BJ51 | AW46: =_xlfn.IFNA(Backend!O51,"") | AX46: =_xlfn.IFNA(IF(D46="","",Backend!BK51),"") -> 10.35 | AY46: =IF(AX46="","",AX46*G46) -> 20.7
A47: 45 | B47: =B46 -> FWR10000 | C47: 2 | D47: H 157 01 030 P | E47: 12 | F47: Belt exit Guide | G47: 1 | H47: Injection Moulding | I47: BOF | J47: CSC | K47: =_xlfn.IFNA(Backend!AN52,"") -> 0 | L47: =IFERROR(AA47,"") | M47: =IFERROR(AW47,"") | N47: =IF(SUM(AB47:AS47)=0,"",SUM(AB47:AS47)) | O47: =IF(SUM(AT47:AV47)=0,"",SUM(AT47:AV47)) | P47: =IF(K47="","",SUM(K47:O47)) -> 0 | Q47: =IF(P47="","",P47*G47) -> 0 | T47: =_xlfn.IFNA(IF(VLOOKUP(D47,Group!C:I,7,0)=0,"",VLOOKUP(D47,Group!C:I,7,0)),"") | U47: =IFERROR(T47*G47,"") | V47: =IFERROR(AY47/U47,"") | AA47: =_xlfn.IFNA(Backend!AO52,"") | AB47: =Backend!AP52 | AC47: =Backend!AQ52 | AD47: =Backend!AR52 -> 0 | AE47: =Backend!AS52 | AF47: =Backend!AT52 | AG47: =Backend!AU52 -> 0 | AH47: =Backend!AV52 | AI47: =Backend!AW52 | ... AV47: =Backend!BJ52 -> 0 | AW47: =_xlfn.IFNA(Backend!O52,"") | AX47: =_xlfn.IFNA(IF(D47="","",Backend!BK52),"") -> 0 | AY47: =IF(AX47="","",AX47*G47) -> 0
...

Sheet Assy_Cost
A1: Assembly(If norms available)
B3: Part No | C3: Process Type | D3: Part Description | E3: PROCESS DESCRIPTION | G3: Assy Type | H3: UOM | I3: No. of Opn. As per UOM | J3: PARTS PER CYCLE | K3: Norms | L3: Process cost/Unit
C4: =_xlfn.IFNA(IF(E4="Surface protection","Surface Protection",IF(VLOOKUP(B4,BOM!$D$1:$I$10000,6,0)="Inhouse","Process-Inhouse",IF(VLOOKUP(B4,BOM!$D$1:$I$10000,6,0)="Inhouse","Process-Inhouse",IF(VLOOKUP(B4,BOM!$D$1:$I$10000,6,0)="BOF","Process-outsourced",IF(VLOOKUP(B4,BOM!$D$1:$I$10000,6,0)="BOSF","Process-Inhouse"))))),"") | D4: =_xlfn.IFNA(VLOOKUP(B4,BOM!D:F,3,0),"") | H4: =_xlfn.IFNA(VLOOKUP(G4,'Process Base'!D:G,4,0),"") | J4: 1 | K4: =_xlfn.IFNA(VLOOKUP(G4,'Process Base'!D:F,3,0),"") | L4: =IFERROR((K4/J4)*I4,"")
C5: =_xlfn.IFNA(IF(E5="Surface protection","Surface Protection",IF(VLOOKUP(B5,BOM!$D$1:$I$10000,6,0)="Inhouse","Process-Inhouse",IF(VLOOKUP(B5,BOM!$D$1:$I$10000,6,0)="Inhouse","Process-Inhouse",IF(VLOOKUP(B5,BOM!$D$1:$I$10000,6,0)="BOF","Process-outsourced",IF(VLOOKUP(B5,BOM!$D$1:$I$10000,6,0)="BOSF","Process-Inhouse"))))),"") | D5: =_xlfn.IFNA(VLOOKUP(B5,BOM!D:F,3,0),"") | H5: =_xlfn.IFNA(VLOOKUP(G5,'Process Base'!D:G,4,0),"") | J5: 1 | K5: =_xlfn.IFNA(VLOOKUP(G5,'Process Base'!D:F,3,0),"") | L5: =IFERROR((K5/J5)*I5,"")
C6: =_xlfn.IFNA(IF(E6="Surface protection","Surface Protection",IF(VLOOKUP(B6,BOM!$D$1:$I$10000,6,0)="Inhouse","Process-Inhouse",IF(VLOOKUP(B6,BOM!$D$1:$I$10000,6,0)="Inhouse","Process-Inhouse",IF(VLOOKUP(B6,BOM!$D$1:$I$10000,6,0)="BOF","Process-outsourced",IF(VLOOKUP(B6,BOM!$D$1:$I$10000,6,0)="BOSF","Process-Inhouse"))))),"") | D6: =_xlfn.IFNA(VLOOKUP(B6,BOM!D:F,3,0),"") | H6: =_xlfn.IFNA(VLOOKUP(G6,'Process Base'!D:G,4,0),"") | J6: 1 | K6: =_xlfn.IFNA(VLOOKUP(G6,'Process Base'!D:F,3,0),"") | L6: =IFERROR((K6/J6)*I6,"")
C7: =_xlfn.IFNA(IF(E7="Surface protection","Surface Protection",IF(VLOOKUP(B7,BOM!$D$1:$I$10000,6,0)="Inhouse","Process-Inhouse",IF(VLOOKUP(B7,BOM!$D$1:$I$10000,6,0)="Inhouse","Process-Inhouse",IF(VLOOKUP(B7,BOM!$D$1:$I$10000,6,0)="BOF","Process-outsourced",IF(VLOOKUP(B7,BOM!$D$1:$I$10000,6,0)="BOSF","Process-Inhouse"))))),"") | D7: =_xlfn.IFNA(VLOOKUP(B7,BOM!D:F,3,0),"") | H7: =_xlfn.IFNA(VLOOKUP(G7,'Process Base'!D:G,4,0),"") | J7: 1 | K7: =_xlfn.IFNA(VLOOKUP(G7,'Process Base'!D:F,3,0),"") | L7: =IFERROR((K7/J7)*I7,"")
C8: =_xlfn.IFNA(IF(E8="Surface protection","Surface Protection",IF(VLOOKUP(B8,BOM!$D$1:$I$10000,6,0)="Inhouse","Process-Inhouse",IF(VLOOKUP(B8,BOM!$D$1:$I$10000,6,0)="Inhouse","Process-Inhouse",IF(VLOOKUP(B8,BOM!$D$1:$I$10000,6,0)="BOF","Process-outsourced",IF(VLOOKUP(B8,BOM!$D$1:$I$10000,6,0)="BOSF","Process-Inhouse"))))),"") | D8: =_xlfn.IFNA(VLOOKUP(B8,BOM!D:F,3,0),"") | H8: =_xlfn.IFNA(VLOOKUP(G8,'Process Base'!D:G,4,0),"") | J8: 1 | K8: =_xlfn.IFNA(VLOOKUP(G8,'Process Base'!D:F,3,0),"") | L8: =IFERROR((K8/J8)*I8,"")
A15: Assembly(If norms not available)
B17: Part No. | C17: Process Type | D17: Part Description | E17: Process Description | F17: Cycle time(Sec) | G17: MHR | H17: Machine rate | I17: No. of Labour | J17: Labour type | K17: Labour rate | L17: Assy cost
B18: =Group!AF2 -> FWR10000 | C18: =_xlfn.IFNA(IF(E18="Surface protection","Surface Protection",IF(VLOOKUP(B18,BOM!$D$1:$I$10000,6,0)="Inhouse","Process-Inhouse",IF(VLOOKUP(B18,BOM!$D$1:$I$10000,6,0)="Inhouse","Process-Inhouse",IF(VLOOKUP(B18,BOM!$D$1:$I$10000,6,0)="BOF","Process-outsourced",IF(VLOOKUP(B18,BOM!$D$1:$I$10000,6,0)="BOSF","Process-Inhouse"))))),"") -> Process-Inhouse | D18: =_xlfn.IFNA(VLOOKUP(B18,BOM!D:F,3,0),"") -> Seat - Driver Pneumatic Suspended | H18: =F18*G18/3600 -> 0 | K18: =I18*IF(J18="Skilled",120,IF(J18="Semi-skilled",100,IF(J18="Unskilled",80,0)))*F18/3600 -> 0 | L18: =H18+K18 -> 0
B19: =Group!AF3 -> H 157 01 464 A | C19: =_xlfn.IFNA(IF(E19="Surface protection","Surface Protection",IF(VLOOKUP(B19,BOM!$D$1:$I$10000,6,0)="Inhouse","Process-Inhouse",IF(VLOOKUP(B19,BOM!$D$1:$I$10000,6,0)="Inhouse","Process-Inhouse",IF(VLOOKUP(B19,BOM!$D$1:$I$10000,6,0)="BOF","Process-outsourced",IF(VLOOKUP(B19,BOM!$D$1:$I$10000,6,0)="BOSF","Process-Inhouse"))))),"") -> Process-Inhouse | D19: =_xlfn.IFNA(VLOOKUP(B19,BOM!D:F,3,0),"") -> SLIDER KIT ASSY | H19: =F19*G19/3600 -> 0 | K19: =I19*IF(J19="Skilled",120,IF(J19="Semi-skilled",100,IF(J19="Unskilled",80,0)))*F19/3600 -> 0 | L19: =H19+K19 -> 0
B20: =Group!AF4 -> H 157 01 270 A | C20: =_xlfn.IFNA(IF(E20="Surface protection","Surface Protection",IF(VLOOKUP(B20,BOM!$D$1:$I$10000,6,0)="Inhouse","Process-Inhouse",IF(VLOOKUP(B20,BOM!$D$1:$I$10000,6,0)="Inhouse","Process-Inhouse",IF(VLOOKUP(B20,BOM!$D$1:$I$10000,6,0)="BOF","Process-outsourced",IF(VLOOKUP(B20,BOM!$D$1:$I$10000,6,0)="BOSF","Process-Inhouse"))))),"") -> Process-Inhouse | D20: =_xlfn.IFNA(VLOOKUP(B20,BOM!D:F,3,0),"") -> Pnematic suspension CV | H20: =F20*G20/3600 -> 0 | K20: =I20*IF(J20="Skilled",120,IF(J20="Semi-skilled",100,IF(J20="Unskilled",80,0)))*F20/3600 -> 0 | L20: =H20+K20 -> 0
B21: =Group!AF5 -> 0 | C21: =_xlfn.IFNA(IF(E21="Surface protection","Surface Protection",IF(VLOOKUP(B21,BOM!$D$1:$I$10000,6,0)="Inhouse","Process-Inhouse",IF(VLOOKUP(B21,BOM!$D$1:$I$10000,6,0)="Inhouse","Process-Inhouse",IF(VLOOKUP(B21,BOM!$D$1:$I$10000,6,0)="BOF","Process-outsourced",IF(VLOOKUP(B21,BOM!$D$1:$I$10000,6,0)="BOSF","Process-Inhouse"))))),"") | D21: =_xlfn.IFNA(VLOOKUP(B21,BOM!D:F,3,0),"") | H21: =F21*G21/3600 -> 0 | K21: =I21*IF(J21="Skilled",120,IF(J21="Semi-skilled",100,IF(J21="Unskilled",80,0)))*F21/3600 -> 0 | L21: =H21+K21 -> 0
B22: =Group!AF6 -> 0 | C22: =_xlfn.IFNA(IF(E22="Surface protection","Surface Protection",IF(VLOOKUP(B22,BOM!$D$1:$I$10000,6,0)="Inhouse","Process-Inhouse",IF(VLOOKUP(B22,BOM!$D$1:$I$10000,6,0)="Inhouse","Process-Inhouse",IF(VLOOKUP(B22,BOM!$D$1:$I$10000,6,0)="BOF","Process-outsourced",IF(VLOOKUP(B22,BOM!$D$1:$I$10000,6,0)="BOSF","Process-Inhouse"))))),"") | D22: =_xlfn.IFNA(VLOOKUP(B22,BOM!D:F,3,0),"") | H22: =F22*G22/3600 -> 0 | K22: =I22*IF(J22="Skilled",120,IF(J22="Semi-skilled",100,IF(J22="Unskilled",80,0)))*F22/3600 -> 0 | L22: =H22+K22 -> 0
B23: =Group!AF7 -> 0 | C23: =_xlfn.IFNA(IF(E23="Surface protection","Surface Protection",IF(VLOOKUP(B23,BOM!$D$1:$I$10000,6,0)="Inhouse","Process-Inhouse",IF(VLOOKUP(B23,BOM!$D$1:$I$10000,6,0)="Inhouse","Process-Inhouse",IF(VLOOKUP(B23,BOM!$D$1:$I$10000,6,0)="BOF","Process-outsourced",IF(VLOOKUP(B23,BOM!$D$1:$I$10000,6,0)="BOSF","Process-Inhouse"))))),"") | D23: =_xlfn.IFNA(VLOOKUP(B23,BOM!D:F,3,0),"") | H23: =F23*G23/3600 -> 0 | K23: =I23*IF(J23="Skilled",120,IF(J23="Semi-skilled",100,IF(J23="Unskilled",80,0)))*F23/3600 -> 0 | L23: =H23+K23 -> 0
B24: =Group!AF8 -> 0 | C24: =_xlfn.IFNA(IF(E24="Surface protection","Surface Protection",IF(VLOOKUP(B24,BOM!$D$1:$I$10000,6,0)="Inhouse","Process-Inhouse",IF(VLOOKUP(B24,BOM!$D$1:$I$10000,6,0)="Inhouse","Process-Inhouse",IF(VLOOKUP(B24,BOM!$D$1:$I$10000,6,0)="BOF","Process-outsourced",IF(VLOOKUP(B24,BOM!$D$1:$I$10000,6,0)="BOSF","Process-Inhouse"))))),"") | D24: =_xlfn.IFNA(VLOOKUP(B24,BOM!D:F,3,0),"") | H24: =F24*G24/3600 -> 0 | K24: =I24*IF(J24="Skilled",120,IF(J24="Semi-skilled",100,IF(J24="Unskilled",80,0)))*F24/3600 -> 0 | L24: =H24+K24 -> 0

Sheet Machining_Process
A1: 1
M2: Cutting speed M/Min
K3: Operation | L3: Steel | M3: SG Iron | N3: Cast Iron | O3: Aluminium | P3: Stainless Steel | Q3: Brass | R3: Bronze | S3: Copper | T3: Copper | U3: Copper
L4: 2 | M4: 3 | N4: 4 | O4: 5 | P4: 6 | Q4: 7 | R4: 8 | S4: 9 | T4: 9 | U4: 9
K5: Drilling | L5: 25 | M5: 50 | N5: 80 | O5: 100 | P5: 20 | Q5: 50 | R5: 35 | S5: 20 | T5: 20 | U5: 20
K6: Face Milling | L6: 100 | M6: 160 | N6: 200 | O6: 350 | P6: 80 | Q6: 190 | R6: 155 | S6: 62 | T6: 62 | U6: 62 | W6: cylinderal grinding | X6: 30-40m/min
K7: Pocket milling | L7: =L6/2 -> 50 | M7: =M6/2 -> 80 | N7: =N6/2 -> 100 | O7: =O6/2 -> 175 | P7: =P6/2 -> 40 | Q7: =Q6/2 -> 95 | R7: =R6/2 -> 77.5 | S7: =S6/2 -> 31 | ... U7: =U6/2 -> 31
K8: Turning | L8: 110 | M8: 150 | N8: 190 | O8: 350 | P8: 100 | Q8: 190 | R8: 155 | S8: 62 | T8: 62 | U8: 62
K9: Tapping | L9: =L5/5 -> 5 | M9: =M5/5 -> 10 | N9: =N5/5 -> 16 | O9: =O5/5 -> 20 | P9: =P5/5 -> 4 | Q9: =Q5/5 -> 10 | R9: =R5/5 -> 7 | S9: =S5/5 -> 4 | ... U9: =U5/5 -> 4
K10: Boring | L10: 110 | M10: 150 | N10: 190 | O10: 350 | P10: 100 | Q10: 190 | R10: 155 | S10: 62 | T10: 62 | U10: 62
K11: Hobbing | L11: 100 | M11: 160 | N11: 200 | O11: 350 | P11: 80 | Q11: 190 | R11: 155 | S11: 62 | T11: 62 | U11: 62 | W11: Reference for Cutting speed for grinding
K12: Gear Grinding | L12: 2500 | W12: https://www.abrasiveengineering.com/speeds.htm
K13: Internal Grinding | L13: 2500
K14: External Grinding | L14: 2500
K15: Surface grinding | L15: 1500
K16: Chamfering
B17: Cycle Time Calculation Master | K17: Spot facing
Q18: <-- Select material type from dropdown list
Q19: <-- Manual input
Q20: <-- Manual entry
T21: Total Machining time | V21: Machining cost | EF21: Table reciprocating speed 30 M/min (500mm/s) considered
F22: Material | T22: =SUMIF(B25:$B$9955,B22,X25:$X$9955) -> 0 | V22: =SUMIF(B25:$B$9955,B22,V25:$V$9955) -> 0 | DM22: Considered grinding allowance 0.3 & Depth of cut 0.025mm -12 pass | DT22: Considered grinding allowance 0.3 & Depth of cut 0.025mm -12 pass | EF22: Considered grinding allowance 0.2 mm & 4 roughing cut 1 finish cut
B23: Part Details | H23: Machining Details | K23: Machining Parameters | Y23: Drilling | AH23: Face Milling | AT23: Pocket Milling | BF23: Turning | BP23: Tapping | BY23: Boring | CI23: Hobbing | CV23: Gear Grinding | DH23: Internal Grinding | DS23: External Grinding | EE23: Surface Grinding
B24: Part No | C24: Process Type | D24: Machining Type | E24: PROCESS DESCRIPTION | F24: QTY | H24: Machine | I24: MHR | J24: Operation | K24: Diameter (Tool/Job) | L24: Length | M24: Width of job | N24: No of pass | O24: No of inserts | P24: Pitch in mm (Tapping) | Q24: No. of teeth (Gears) | R24: Height of teeth (Gears) | S24: Module (Gears) | T24: Time in Sec | U24: Cost /part | V24: TOTAL VALUE ADD | W24: REMARKS | X24: Total Time in Sec | Y24: Final Drill Ø | Z24: Depth | AA24: CS | AB24: RPM | AC24: Feed mm/rev | AD24: Time | AE24: Rapid movement + TC time | AF24: Total Drilling Time | AH24: Cutter Ø | AI24: Length | AJ24: Width | AK24: No of pass | AL24: No of insert | AM24: CS | AN24: RPM | AO24: Feed mm/rev | AP24: Time | AQ24: Rapid movement + TC time | AR24: Total Milling Time | AT24: Cutter Ø | AU24: Length | AV24: Width | AW24: No of pass | AX24: No of insert | AY24: CS | AZ24: RPM | BA24: Feed mm/rev | BB24: Time | BC24: Rapid movement + TC time | BD24: Total Milling Time | BF24: Work Ø | BG24: Turning Length | BH24: No of pass | BI24: CS | BJ24: RPM | BK24: Feed mm/rev | BL24: Time | BM24: Rapid movement + TC time | BN24: Total Turning Time | BP24: Nominal Ø of the thread | BQ24: Tapping Depth | BR24: Pitch in mm | BS24: CS | BT24: RPM | BU24: Time | BV24: Rapid movement + TC time | BW24: Total Tapping Time | BY24: Hole Ø | BZ24: Hole Length | CA24: No of pass | CB24: CS | CC24: RPM | CD24: Feed mm/rev | CE24: Time | CF24: Rapid movement + TC time | CG24: Total Boring Time | CI24: Blank dia. | CJ24: length of job | CK24: Height of teeth | CL24: CS | CM24: RPM | CN24: No. of teeth | CO24: Module | CP24: Hob Dia. | CQ24: Feed mm/rev | CR24: Time | CS24: Rapid movement + TC time | CT24: Total Hobbing Time | CV24: Gear dia. | CW24: length of job | CX24: Height of teeth | CY24: Cutting speed | CZ24: RPM of wheel | DA24: Diameter of the wheel | DB24: No. of teeth | DC24: Feed mm/rev | DD24: Time | DE24: Rapid movement + TC time | DF24: Total Grinding Time | DH24: Diameter of job | DI24: Length of job | DJ24: Pass | DK24: Width of wheel | DL24: CS for workpiece | DM24: Work RPM | DN24: Feed mm/rev | DO24: Time | DP24: Rapid movement + TC time | DQ24: Total Grinding Time | DS24: Diameter of job | DT24: Length of job | DU24: Pass | DV24: Width of wheel | DW24: CS | DX24: Work RPM | DY24: Feed mm/rev | DZ24: Time | EA24: Rapid movement + TC time | EB24: Total Grinding Time | EE24: Length of job | EF24: Width of job | EG24: Width of wheel | EH24: Time | EI24: Rapid movement + TC time | EJ24: Total Grinding Time
B25: =B22 -> 0 | C25: =_xlfn.IFNA(VLOOKUP(B25,BOM!$D$1:$H$10000,5,0),"") | E25: Loading to the machine | F25: 1 | T25: =IF(J25="Drilling",AF25,IF(J25="Face Milling",AR25,IF(J25="Pocket Milling",BD25,IF(J25="Turning",BN25,IF(J25="Tapping",BW25,IF(J25="Boring",CG25,IF(J25="Chamfering",5,IF(J25="Spot facing",10,IF(J25="Hobbing",CT25,IF(J25="Gear grinding",DF25,IF(J25="Internal Grinding",DQ25,IF(J25="External Grinding",EB25,IF(J25="Surface grinding",EJ25,0))))))))))))) -> 0 | U25: =I25/3600*T25 -> 0 | V25: =U25*F25 -> 0 | X25: =T25*F25 -> 0 | Y25: =K25 -> 0 | Z25: =L25+Y25*0.3 -> 0 | AA25: =VLOOKUP(Y$23,$K$3:$S$17,HLOOKUP(VLOOKUP(B25,B:H,7,0),$3:$4,2,0),0) -> #N/A | AB25: =MIN(IFERROR(AA25*1000/(PI()*Y25),0),5000) -> 0 | AC25: =IF(K25<15,0.05,0.1) -> 0.05 | AD25: =IFERROR((Z25+3)/(AB25*AC25/60),0) -> 0 | AE25: 5 | AF25: =AD25+AE25 -> 5 | AH25: =K25 -> 0 | AI25: =L25 -> 0 | AJ25: =M25 -> 0 | AK25: =N25 -> 0 | AL25: =O25 -> 0 | AM25: =VLOOKUP(AH$23,$K$3:$S$17,HLOOKUP(VLOOKUP(B25,B:H,7,0),$3:$4,2,0),0) -> #N/A | AN25: =MIN(IFERROR((AM25*1000/(PI()*AH25)),0),5000) -> 0 | AO25: =0.05*AL25 -> 0 | AP25: =IFERROR(((AI25+(AH25+10)+IF(AJ25<AH25,0,((CEILING(AJ25/AH25,1)-1)*AI25)+((CEILING(AJ25/AH25,1)-1)*AH25)))/(AO25*AN25/60)),0)*AK25 -> 0 | AQ25: 5 | AR25: =AP25+AQ25 -> 5 | AT25: =K25 -> 0 | AU25: =L25 -> 0 | AV25: =M25 -> 0 | AW25: =N25 -> 0 | AX25: =O25 -> 0 | AY25: =VLOOKUP(AT$23,$K$3:$S$17,HLOOKUP(VLOOKUP(B25,B:H,7,0),$3:$4,2,0),0) -> #N/A | AZ25: =MIN(IFERROR((AY25*1000/(PI()*AT25)),0),5000) -> 0 | BA25: =0.03*AX25 -> 0 | BB25: =IFERROR(((AU25+(AT25+10)+IF(AV25<AT25,0,((CEILING(AV25/AT25,1)-1)*AU25)+((CEILING(AV25/AT25,1)-1)*AT25)))/(BA25*AZ25/60)),0)*AW25 -> 0 | BC25: 5 | BD25: =BB25+BC25 -> 5 | BF25: =K25 -> 0 | BG25: =L25 -> 0 | BH25: =N25 -> 0 | BI25: =VLOOKUP(BF$23,$K$3:$S$17,HLOOKUP(VLOOKUP(B25,B:H,7,0),$3:$4,2,0),0) -> #N/A | BJ25: =MIN(IFERROR(BI25*1000/(PI()*BF25),0),5000) -> 0 | BK25: 0.1 | BL25: =IFERROR((BG25+3)/(BJ25*BK25/60),0)*BH25 -> 0 | BM25: 2 | BN25: =BL25+BM25 -> 2 | BP25: =K25 -> 0 | BQ25: =L25 -> 0 | BR25: =P25 -> 0 | BS25: =VLOOKUP(BP$23,$K$3:$S$17,HLOOKUP(VLOOKUP(B25,B:H,7,0),$3:$4,2,0),0) -> #N/A | BT25: =MIN(IFERROR(BS25*1000/(PI()*BP25),0),400) -> 0 | BU25: =IFERROR((BQ25+3)/(BT25*BR25/60),0)*2 -> 0 | BV25: 5 | BW25: =BU25+BV25 -> 5 | BY25: =K25 -> 0 | BZ25: =L25 -> 0 | CA25: =N25 -> 0 | CB25: =VLOOKUP(BY$23,$K$3:$S$17,HLOOKUP(VLOOKUP(B25,B:H,7,0),$3:$4,2,0),0) -> #N/A | CC25: =MIN(IFERROR(CB25*1000/(PI()*BY25),0),5000) -> 0 | CD25: 0.05 | CE25: =IFERROR((BZ25+3)/(CC25*CD25/60),0)*CA25 -> 0 | CF25: 5 | CG25: =CE25+CF25 -> 5 | CI25: =K25 -> 0 | CJ25: =L25 -> 0 | CK25: =R25 -> 0 | CL25: =VLOOKUP(CI$23,$K$3:$S$17,HLOOKUP(VLOOKUP(B25,B:H,7,0),$3:$4,2,0),0) -> #N/A | CM25: =MIN(IFERROR(CL25*1000/(PI()*CP25),0),5000) -> 0 | CN25: =Q25 -> 0 | CO25: =S25 -> 0 | CP25: =9.7903*CO25+41.578 -> 41.578 | CQ25: 1.5 | CR25: =IFERROR((((SQRT((CP25*CK25-CK25^2))+CJ25+5)*CN25)/(CM25*CQ25))*60,0) -> 0 | CS25: 5 | CT25: =CR25+CS25 -> 5 | CV25: =K25 -> 0 | CW25: =L25 -> 0 | CX25: =R25 -> 0 | CY25: =VLOOKUP(CV$23,$K$3:$S$17,HLOOKUP(VLOOKUP(B25,B:H,7,0),$3:$4,2,0),0) -> #N/A | CZ25: =MIN(IFERROR(CY25*1000/(PI()*DA25),0),5000) -> 0 | DA25: 300 | DB25: =Q25 -> 0 | DC25: 0.4 | DD25: =IFERROR((((SQRT((DA25*CX25-CX25^2))+CW25+5)*DB25)/(DC25*CZ25))*60,0) -> 0 | DE25: 5 | DF25: =DD25+DE25 -> 5 | DH25: =K25 -> 0 | DI25: =L25 -> 0 | DJ25: 12 | DK25: 30 | DL25: 15 | DM25: =MIN(IFERROR(DL25*1000/(PI()*DH25),0),5000) -> 0 | DN25: =DK25/2 -> 15 | DO25: =IFERROR(((DI25+DK25)*2)/(DM25*DN25/60),0)*DJ25 -> 0 | DP25: 5 | DQ25: =DO25+DP25 -> 5 | DS25: =K25 -> 0 | DT25: =L25 -> 0 | DU25: 12 | DV25: 30 | DW25: 15 | DX25: =MIN(IFERROR(DW25*1000/(PI()*DS25),0),5000) -> 0 | DY25: =DV25/2 -> 15 | DZ25: =IFERROR(((DT25+DV25)*2)/(DX25*DY25/60),0)*DU25 -> 0 | EA25: 5 | EB25: =DZ25+EA25 -> 5 | EE25: =L25 -> 0 | EF25: =M25 -> 0 | EG25: 30 | EH25: =(EE25+30)/500*CEILING((EF25+EG25+3)/(EG25/6),INT(EG25/6))*4+(EE25+30)/500*CEILING((EF25+EG25+3)/(EG25/10),INT(EG25/10)) -> 3.12 | EI25: 3 | EJ25: =EH25+EI25 -> 6.12
